Workbook
Name PRINT_AREA_MI: #N/A
Name 七: !#REF!
Name 七10一工程費: !#REF!
Name 七10二安全措施費: !#REF!
Name 七10三安衛費: !#REF!
Name 七10五品管費: !#REF!
Name 七10六稅什費: !#REF!
Name 七10四保險費: !#REF!
Name 七10稅什比: !#REF!
Name 七10總計: !#REF!
Name 九01Db1: !#REF!
Name 九01七: !#REF!
Name 九01二: !#REF!
Name 九01三: !#REF!
Name 九01五: !#REF!
Name 九01六: !#REF!
Name 九01四: !#REF!
Name 二: !#REF!
Name 三: !#REF!
Name 五: !#REF!
Name 仁710Db2計量: !#REF!
Name 仁710Db2計價: !#REF!
Name 仁810Db2合約單價: !#REF!
Name 仁901Db2本日累計: !#REF!
Name 仁901Db2合約數量: !#REF!
Name 六: !#REF!
Name 日期: !#REF!
Name 四: !#REF!
Name 欄標題1: " "

Sheet 總表 
A1: 新竹海水淡化廠興建及操作維護(興建部分) 材料設備送審統計總表
A2: 項目 | B2: 項次 | C2: 類別 | D2: 應送審 | E2: 未送審 | F2: 已送審 | G2: 已核定 | H2: 審查中 | I2: 修正中 | J2: 完成率(核定/應送)
A3: 材料設備 | B3: 10-1 | C3: 材料試驗單位 | D3: ='10-1材料試驗單位'!C66 -> 21 | E3: ='10-1材料試驗單位'!C67 -> 0 | F3: =G3+H3+I3 -> 21 | G3: ='10-1材料試驗單位'!C68 -> 19 | H3: ='10-1材料試驗單位'!C69 -> 2 | I3: ='10-1材料試驗單位'!C70 -> 0 | J3: =G3/D3 -> 0.9047619 | K3: 材料檢驗單位
B4: 10-2 | C4: 土建 | D4: ='10-2土建'!H161 -> 73 | E4: ='10-2土建'!H162 -> 5 | F4: =G4+H4+I4 -> 68 | G4: ='10-2土建'!H163 -> 64 | H4: ='10-2土建'!H164 -> 0 | I4: ='10-2土建'!H165 -> 4 | J4: =G4/D4 -> 0.87671233 | K4: 鋼筋/混凝土/鋼構/道路
B5: 10-3 | C5: 取排水管線 | D5: ='10-3取排水(宏華)'!C38 -> 10 | E5: ='10-3取排水(宏華)'!C39 -> 0 | F5: =G5+H5+I5 -> 10 | G5: ='10-3取排水(宏華)'!C40 -> 6 | H5: ='10-3取排水(宏華)'!C41 -> 4 | I5: ='10-3取排水(宏華)'!C42 -> 0 | J5: =G5/D5 -> 0.6 | K5: 管線/取水頭/排水設施/浮燈/拋石
B6: 10-4 | C6: 建築裝修 | D6: ='10-4 建築裝修'!F169 -> 54 | E6: ='10-4 建築裝修'!F170 -> 50 | F6: =G6+H6+I6 -> 4 | G6: ='10-4 建築裝修'!F171 -> 4 | H6: ='10-4 建築裝修'!F172 -> 0 | I6: ='10-4 建築裝修'!F173 -> 0 | J6: =G6/D6 -> 0.074074074 | K6: 參照土建規範
B7: 10-5 | C7: 消防/空調/給排水 | D7: ='10-5消防空調給排水'!E49 -> 14 | E7: ='10-5消防空調給排水'!E50 -> 13 | F7: =G7+H7+I7 -> 1 | G7: ='10-5消防空調給排水'!E51 -> 0 | H7: ='10-5消防空調給排水'!E52 -> 0 | I7: ='10-5消防空調給排水'!E53 -> 1 | J7: =G7/D7 -> 0 | K7: 參照廠區消防、空調及給排水規範
B8: 10-6 | C8: 機械設備 | D8: ='10-6機械設備'!F211 -> 68 | E8: ='10-6機械設備'!F212 -> 12 | F8: =G8+H8+I8 -> 56 | G8: ='10-6機械設備'!F213 -> 45 | H8: ='10-6機械設備'!F214 -> 10 | I8: ='10-6機械設備'!F215 -> 1 | J8: =G8/D8 -> 0.66176471 | K8: 參照第六冊規範
B9: 10-7 | C9: 電力/儀控 | D9: ='10-7電力儀控'!G253 -> 82 | E9: ='10-7電力儀控'!G254 -> 61 | F9: =G9+H9+I9 -> 21 | G9: ='10-7電力儀控'!G255 -> 4 | H9: ='10-7電力儀控'!G256 -> 16 | I9: ='10-7電力儀控'!G257 -> 1 | J9: =G9/D9 -> 0.048780488 | K9: 參照第九冊規範
B10: 10-8 | C10: 管線/閥類 | D10: ='10-8管線閥類'!F64 -> 19 | E10: ='10-8管線閥類'!F65 -> 18 | F10: =G10+H10+I10 -> 1 | G10: ='10-8管線閥類'!F66 -> 0 | H10: ='10-8管線閥類'!F67 -> 1 | I10: ='10-8管線閥類'!F68 -> 0 | J10: =G10/D10 -> 0
B11: 10-9 | C11: 景觀/植栽 | D11: ='10-9景觀植栽'!E37 -> 7 | E11: ='10-9景觀植栽'!E38 -> 7 | F11: =G11+H11+I11 -> 0 | G11: ='10-9景觀植栽'!E39 -> 0 | H11: ='10-9景觀植栽'!E40 -> 0 | I11: ='10-9景觀植栽'!E41 -> 0 | J11: =G11/D11 -> 0
B12: 合計 | D12: =SUM(D3:D11) -> 348 | E12: =SUM(E3:E11) -> 166 | F12: =SUM(F3:F11) -> 182 | G12: =SUM(G3:G11) -> 142 | H12: =SUM(H3:H11) -> 33 | I12: =SUM(I3:I11) -> 7 | J12: =G12/D12 -> 0.40804598

Sheet 10-1材料試驗單位
A1: 新竹海水淡化廠興建及操作維護(興建部分) 材料試驗單位送審管制總表
A2: 項次 | B2: 編碼 | C2: 文件 | D2: 類別 | E2: 規範 | F2: 圖面 | G2: 廠商 | H2: 預定送審 (進場前60天) | I2: 預定廠驗 (進場前30天) | J2: 預定進場 | K2: 送審預警天數(60天內才顯示) | L2: 送審延遲 | M2: 程序 | N2: 版次 | O2: 審查情形 | Z2: 備註
K3: 辦理預警 | O3: 統包商 | Q3: 監造 | T3: 專管 | W3: 機關(北水分署)
O4: 日期 | P4: 文號 | Q4: 日期 | R4: 文號 | S4: 結果 | T4: 日期 | U4: 文號 | V4: 結果 | W4: 日期 | X4: 文號 | Y4: 結果
A5: 1 | B5: M-03-MA-39-006 | C5: 材料試驗室單位-今塘 | K5: =IF(H5="","",IF(O5<>"","",IF(AND(O5="",H5-TODAY()<=60),H5-TODAY(),""))) | L5: =IF(AND(ISNUMBER(H5),ISNUMBER(O5)),H5-O5,"") | M5: 核定 | O5: 45660 | P5: 鼎水資字第 1140000003號 | Q5: 45677 | R5: 艾奕康水字第1140002159號 | S5: 審查同意 | T5: — | U5: — | V5: — | W5: 45681 | X5: 水北多字第11453008120號 | Y5: 核定
A6: 2 | B6: M-03-MA-39-007 | C6: 材料試驗室單位-日鼎 | K6: =IF(H6="","",IF(O6<>"","",IF(AND(O6="",H6-TODAY()<=60),H6-TODAY(),""))) | L6: =IF(AND(ISNUMBER(H6),ISNUMBER(O6)),H6-O6,"") | M6: 核定 | O6: 45659 | P6: 鼎水資字第 1130000981號 | Q6: 45677 | R6: 艾奕康水字第1140002159號 | S6: 審查同意 | T6: — | U6: — | V6: — | W6: 45681 | X6: 水北多字第11453008120號 | Y6: 核定
A7: 3 | B7: M-03-MA-39-0008 | C7: 材料試驗室單位-SGS | K7: =IF(H7="","",IF(O7<>"","",IF(AND(O7="",H7-TODAY()<=60),H7-TODAY(),""))) | L7: =IF(AND(ISNUMBER(H7),ISNUMBER(O7)),H7-O7,"") | M7: 核定 | N7: 1-A | O7: 45744 | P7: 鼎水資字第1140000272號 | Q7: 45754 | R7: 艾奕康水字第1140010924號 | S7: 審查同意 | T7: 45754 | U7: 艾奕康水字第1140010924號 | V7: 審定 | W7: 45755 | X7: 水北多字第11453034740號 | Y7: 核定
K8: =IF(H8="","",IF(O8<>"","",IF(AND(O8="",H8-TODAY()<=60),H8-TODAY(),""))) | L8: =IF(AND(ISNUMBER(H8),ISNUMBER(O8)),H8-O8,"")
K9: =IF(H9="","",IF(O9<>"","",IF(AND(O9="",H9-TODAY()<=60),H9-TODAY(),""))) | L9: =IF(AND(ISNUMBER(H9),ISNUMBER(O9)),H9-O9,"")
A10: 4 | B10: M-39-MA-39-0008 | C10: 材料試驗室單位-光宜 | K10: =IF(H10="","",IF(O10<>"","",IF(AND(O10="",H10-TODAY()<=60),H10-TODAY(),""))) | L10: =IF(AND(ISNUMBER(H10),ISNUMBER(O10)),H10-O10,"") | M10: 核定 | N10: 0-A | O10: 45744 | P10: 鼎水資字第1140000273號 | Q10: 45754 | R10: 艾奕康水字第1140010927號 | S10: 審查同意 | T10: 45754 | U10: 艾奕康水字第1140010927號 | V10: 審定 | W10: 45755 | X10: 水北多字第11453034740號 | Y10: 核定
K11: =IF(H11="","",IF(O11<>"","",IF(AND(O11="",H11-TODAY()<=60),H11-TODAY(),""))) | L11: =IF(AND(ISNUMBER(H11),ISNUMBER(O11)),H11-O11,"")
K12: =IF(H12="","",IF(O12<>"","",IF(AND(O12="",H12-TODAY()<=60),H12-TODAY(),""))) | L12: =IF(AND(ISNUMBER(H12),ISNUMBER(O12)),H12-O12,"")
A13: 5 | B13: S-SD04-004 | C13: 材料試驗室單位-遠翔 | K13: =IF(H13="","",IF(O13<>"","",IF(AND(O13="",H13-TODAY()<=60),H13-TODAY(),""))) | L13: =IF(AND(ISNUMBER(H13),ISNUMBER(O13)),H13-O13,"") | M13: 核定 | N13: 1-A | O13: 45786 | P13: 鼎水資字第 1140000405號 | Q13: 45789 | R13: 艾奕康新竹海淡監字第1140512-3 號 | S13: 審查同意 | T13: 45791 | U13: 艾奕康水字第1140015530號 | V13: 審定 | W13: 45799 | X13: 水北多字第11453051520號 | Y13: 核定
K14: =IF(H14="","",IF(O14<>"","",IF(AND(O14="",H14-TODAY()<=60),H14-TODAY(),""))) | L14: =IF(AND(ISNUMBER(H14),ISNUMBER(O14)),H14-O14,"")
K15: =IF(H15="","",IF(O15<>"","",IF(AND(O15="",H15-TODAY()<=60),H15-TODAY(),""))) | L15: =IF(AND(ISNUMBER(H15),ISNUMBER(O15)),H15-O15,"")
A16: 6 | B16: S-SD10-002 | C16: 料試驗室單位-華光 | K16: =IF(H16="","",IF(O16<>"","",IF(AND(O16="",H16-TODAY()<=60),H16-TODAY(),""))) | L16: =IF(AND(ISNUMBER(H16),ISNUMBER(O16)),H16-O16,"") | M16: 核定 | N16: 0-A | O16: 45786 | P16: 鼎水資字第 1140000406號 | Q16: 45789 | R16: 艾奕康新竹海淡監字第1140512-2 號 | S16: 審查同意 | T16: 45791 | U16: 艾奕康水字第1140015530號 | V16: 審定 | W16: 45799 | X16: 水北多字第11453051520號 | Y16: 核定
K17: =IF(H17="","",IF(O17<>"","",IF(AND(O17="",H17-TODAY()<=60),H17-TODAY(),""))) | L17: =IF(AND(ISNUMBER(H17),ISNUMBER(O17)),H17-O17,"")
K18: =IF(H18="","",IF(O18<>"","",IF(AND(O18="",H18-TODAY()<=60),H18-TODAY(),""))) | L18: =IF(AND(ISNUMBER(H18),ISNUMBER(O18)),H18-O18,"")
A19: 7 | B19: S-SD05-003 | C19: 材料試驗室單位-禾洋/遠宜 | K19: =IF(H19="","",IF(O19<>"","",IF(AND(O19="",H19-TODAY()<=60),H19-TODAY(),""))) | L19: =IF(AND(ISNUMBER(H19),ISNUMBER(O19)),H19-O19,"") | M19: 核定 | N19: 1-A | O19: 45786 | P19: 鼎水資字第 1140000407號 | Q19: 45789 | R19: 艾奕康新竹海淡監字第1140512-4 號 | S19: 審查同意 | T19: 45791 | U19: 艾奕康水字第1140015530號 | V19: 審定 | W19: 45799 | X19: 水北多字第11453051520號 | Y19: 核定
K20: =IF(H20="","",IF(O20<>"","",IF(AND(O20="",H20-TODAY()<=60),H20-TODAY(),""))) | L20: =IF(AND(ISNUMBER(H20),ISNUMBER(O20)),H20-O20,"")
K21: =IF(H21="","",IF(O21<>"","",IF(AND(O21="",H21-TODAY()<=60),H21-TODAY(),""))) | L21: =IF(AND(ISNUMBER(H21),ISNUMBER(O21)),H21-O21,"")
A22: 8 | B22: S-SD02-007 | C22: 材料試驗室單位-豐澤 | K22: =IF(H22="","",IF(O22<>"","",IF(AND(O22="",H22-TODAY()<=60),H22-TODAY(),""))) | L22: =IF(AND(ISNUMBER(H22),ISNUMBER(O22)),H22-O22,"") | M22: 核定 | N22: 1-A | O22: 46000 | P22: 鼎水資字第1140001465號 | Q22: 46009 | R22: 艾奕康水字第1140035008號 | S22: 審查同意 | T22: 46010 | U22: 艾奕康水字第1140035706號 | V22: 審定 | W22: 46048 | X22: 水北多字第11522003790號 | Y22: 核定
K23: =IF(H23="","",IF(O23<>"","",IF(AND(O23="",H23-TODAY()<=60),H23-TODAY(),""))) | L23: =IF(AND(ISNUMBER(H23),ISNUMBER(O23)),H23-O23,"")
K24: =IF(H24="","",IF(O24<>"","",IF(AND(O24="",H24-TODAY()<=60),H24-TODAY(),""))) | L24: =IF(AND(ISNUMBER(H24),ISNUMBER(O24)),H24-O24,"")
A25: 9 | B25: S-SD12-006 | C25: 材料試驗室單位-鋼凝 | K25: =IF(H25="","",IF(O25<>"","",IF(AND(O25="",H25-TODAY()<=60),H25-TODAY(),""))) | L25: =IF(AND(ISNUMBER(H25),ISNUMBER(O25)),H25-O25,"") | M25: 核定 | N25: 0-A | O25: 45800 | P25: 鼎水資字第 1140000480號 | Q25: 45805 | R25: 艾奕康新竹海淡監字第1140528-3 號 | S25: 審查同意 | T25: 45810 | U25: 艾奕康水字第1140017030號 | V25: 審定 | W25: 45814 | X25: 水北多字第11453057890號 | Y25: 核定
K26: =IF(H26="","",IF(O26<>"","",IF(AND(O26="",H26-TODAY()<=60),H26-TODAY(),""))) | L26: =IF(AND(ISNUMBER(H26),ISNUMBER(O26)),H26-O26,"")
K27: =IF(H27="","",IF(O27<>"","",IF(AND(O27="",H27-TODAY()<=60),H27-TODAY(),""))) | L27: =IF(AND(ISNUMBER(H27),ISNUMBER(O27)),H27-O27,"")
A28: 10 | B28: S-SD01-005 | C28: 材料試驗室單位-正昌 | K28: =IF(H28="","",IF(O28<>"","",IF(AND(O28="",H28-TODAY()<=60),H28-TODAY(),""))) | L28: =IF(AND(ISNUMBER(H28),ISNUMBER(O28)),H28-O28,"") | M28: 核定 | N28: 1-A | O28: 45800 | P28: 鼎水資字第 1140000481 號 | Q28: 45805 | R28: 艾奕康新竹海淡監字第1140528-1號 | S28: 審查同意 | T28: 45810 | U28: 艾奕康水字第1140017030號 | V28: 審定 | W28: 45814 | X28: 水北多字第11453057890號 | Y28: 核定
K29: =IF(H29="","",IF(O29<>"","",IF(AND(O29="",H29-TODAY()<=60),H29-TODAY(),""))) | L29: =IF(AND(ISNUMBER(H29),ISNUMBER(O29)),H29-O29,"")
K30: =IF(H30="","",IF(O30<>"","",IF(AND(O30="",H30-TODAY()<=60),H30-TODAY(),""))) | L30: =IF(AND(ISNUMBER(H30),ISNUMBER(O30)),H30-O30,"")
A31: 11 | B31: S-SD3-008 | C31: 材料試驗室單位-富群 | K31: =IF(H31="","",IF(O31<>"","",IF(AND(O31="",H31-TODAY()<=60),H31-TODAY(),""))) | L31: =IF(AND(ISNUMBER(H31),ISNUMBER(O31)),H31-O31,"") | M31: 核定 | N31: 1-A | O31: 45814 | P31: 鼎水資字第 1140000534 號 | Q31: 45819 | R31: 艾奕康新竹海淡監字第1140611-1 號 | S31: 審查同意 | T31: 45821 | U31: 艾奕康水字第1140018472號 | V31: 審定 | W31: 114/6/19 | X31: 水北多字第11453063010號 | Y31: 核定
K32: =IF(H32="","",IF(O32<>"","",IF(AND(O32="",H32-TODAY()<=60),H32-TODAY(),""))) | L32: =IF(AND(ISNUMBER(H32),ISNUMBER(O32)),H32-O32,"")
K33: =IF(H33="","",IF(O33<>"","",IF(AND(O33="",H33-TODAY()<=60),H33-TODAY(),""))) | L33: =IF(AND(ISNUMBER(H33),ISNUMBER(O33)),H33-O33,"")
A34: 12 | B34: S-SD13-009 | C34: 材料試驗室單位-惠凱 | K34: =IF(H34="","",IF(O34<>"","",IF(AND(O34="",H34-TODAY()<=60),H34-TODAY(),""))) | L34: =IF(AND(ISNUMBER(H34),ISNUMBER(O34)),H34-O34,"") | M34: 核定 | N34: 0-A | O34: 45999 | P34: 鼎水資字第1140001464號 | Q34: 46009 | R34: 艾奕康水字第1140034901號 | S34: 審查同意 | T34: 46010 | U34: 艾奕康水字第1140035705號 | V34: 審定 | W34: 46056 | X34: 水北多字第11522005570號 | Y34: 核定
K35: =IF(H35="","",IF(O35<>"","",IF(AND(O35="",H35-TODAY()<=60),H35-TODAY(),""))) | L35: =IF(AND(ISNUMBER(H35),ISNUMBER(O35)),H35-O35,"")
K36: =IF(H36="","",IF(O36<>"","",IF(AND(O36="",H36-TODAY()<=60),H36-TODAY(),""))) | L36: =IF(AND(ISNUMBER(H36),ISNUMBER(O36)),H36-O36,"")
A37: 13 | B37: S-SD14-010 | C37: 非破壞檢測-政鋼 | K37: =IF(H37="","",IF(O37<>"","",IF(AND(O37="",H37-TODAY()<=60),H37-TODAY(),""))) | L37: =IF(AND(ISNUMBER(H37),ISNUMBER(O37)),H37-O37,"") | M37: 核定 | N37: 0-A | O37: 46000 | P37: 鼎水資字第1140001465號 | Q37: 46009 | R37: 艾奕康水字第1140035008號 | S37: 審查同意 | T37: 46010 | U37: 艾奕康水字第1140035706號 | V37: 審定 | W37: 46048 | X37: 水北多字第11522003790號 | Y37: 核定
K38: =IF(H38="","",IF(O38<>"","",IF(AND(O38="",H38-TODAY()<=60),H38-TODAY(),""))) | L38: =IF(AND(ISNUMBER(H38),ISNUMBER(O38)),H38-O38,"")
K39: =IF(H39="","",IF(O39<>"","",IF(AND(O39="",H39-TODAY()<=60),H39-TODAY(),""))) | L39: =IF(AND(ISNUMBER(H39),ISNUMBER(O39)),H39-O39,"")
A40: 14 | B40: S-SD15-011 | C40: 明研科技 | K40: =IF(H40="","",IF(O40<>"","",IF(AND(O40="",H40-TODAY()<=60),H40-TODAY(),""))) | L40: =IF(AND(ISNUMBER(H40),ISNUMBER(O40)),H40-O40,"") | M40: 核定 | N40: 0-A | O40: 46057 | P40: 宏海淡工字第115021101號 | Q40: 46059 | R40: 艾奕康水字第1150002561號 | S40: 審查同意 | T40: 46062 | U40: 艾奕康水字第1150003976號 | V40: 審定 | W40: 46062 | X40: 水北多字第11553016390號 | Y40: 核定
...

Sheet 10-2土建
E1: 新竹海水淡化廠興建及操作維護(興建部分) 土建材料送審管制總表
A2: 窗口負責人 | B2: 品管現用版本項次 | E2: 項次 | F2: 編碼 | G2: English | H2: 文件 | I2: English | J2: 類別 | K2: 規範 | L2: 圖面 | M2: 廠商 | N2: 預定送審 (進場前60天) | O2: 預定廠驗 (進場前30天) | P2: 預定進場 | Q2: 送審預警天數(60天內才顯示) | R2: 送審延遲 | S2: 程序 | T2: 版次 | U2: 審查情形 | AF2: 備註
Q3: 辦理預警 | U3: 統包商 | W3: 監造 | Z3: 專管 | AC3: 機關(北水分署)
U4: 日期 | V4: 文號 | W4: 日期 | X4: 文號 | Y4: 結果 | Z4: 日期 | AA4: 文號 | AB4: 結果 | AC4: 日期 | AD4: 文號 | AE4: 結果
E5: 1 | F5: M-01-MA-14-001 | H5: 擠壓砂樁 | J5: 土木 | K5: 02361A擠壓砂樁 | M5: 佾泰/康鴻 | Q5: =IF(N5="","",IF(U5<>"","",IF(AND(U5="",N5-TODAY()<=60),N5-TODAY(),""))) | R5: =IF(AND(ISNUMBER(N5),ISNUMBER(U5)),N5-U5,"") | S5: 核定 | T5: 0-A | U5: 45747 | V5: 鼎水資字第1140000276號 | W5: 45757 | X5: 艾奕康水字第1140011908號 | Y5: 審查同意 | Z5: 45757 | AA5: 艾奕康水字第1140011908號 | AB5: =IF(Z5="","",IF(Y5="檢退","檢退",IF(Y5="審查同意","審定","檢退"))) -> 審定 | AC5: 45758 | AD5: 水北多字第11453037020號 | AE5: =IF(AC5="","",IF(AB5="檢退","請修正",IF(AB5="請備查","備查",IF(AB5="審定","核定","請修正")))) -> 核定
E6: 2 | F6: M-01-MA-02-002 | H6: 鋼筋SD280 | J6: 土木 | K6: 03210 鋼筋 | M6: 博大 | N6: =IF(P6="","",P6-60) -> 45793 | P6: 45853 | Q6: =IF(N6="","",IF(U6<>"","",IF(AND(U6="",N6-TODAY()<=60),N6-TODAY(),""))) | R6: =IF(AND(ISNUMBER(N6),ISNUMBER(U6)),N6-U6,"") -> 36 | S6: 核定 | T6: 0-A | U6: 45757 | V6: 鼎水資字第 1140000305 號函 | W6: 45762 | X6: 艾奕康新竹海淡監字第1140415-1 號 | Y6: 審查同意 | Z6: 45765 | AA6: 艾奕康水字第1140012844號 | AB6: =IF(Z6="","",IF(Y6="檢退","檢退",IF(Y6="審查同意","審定","檢退"))) -> 審定 | AC6: 45775 | AD6: 水北多字第11453040750號 | AE6: =IF(AC6="","",IF(AB6="檢退","請修正",IF(AB6="請備查","備查",IF(AB6="審定","核定","請修正")))) -> 核定
E7: 3 | F7: M-01-MA-02-002 | H7: 鋼筋SD280W | J7: 土木 | K7: 03210 鋼筋 | M7: 博大 | N7: =IF(P7="","",P7-60) -> 45793 | P7: 45853 | Q7: =IF(N7="","",IF(U7<>"","",IF(AND(U7="",N7-TODAY()<=60),N7-TODAY(),""))) | R7: =IF(AND(ISNUMBER(N7),ISNUMBER(U7)),N7-U7,"") -> 36 | S7: 核定 | T7: 0-A | U7: 45757 | V7: 鼎水資字第 1140000305 號函 | W7: 45762 | X7: 艾奕康新竹海淡監字第1140415-1 號 | Y7: 審查同意 | Z7: 45765 | AA7: 艾奕康水字第1140012844號 | AB7: =IF(Z7="","",IF(Y7="檢退","檢退",IF(Y7="審查同意","審定","檢退"))) -> 審定 | AC7: 45775 | AD7: 水北多字第11453040750號 | AE7: =IF(AC7="","",IF(AB7="檢退","請修正",IF(AB7="請備查","備查",IF(AB7="審定","核定","請修正")))) -> 核定
E8: 4 | F8: M-01-MA-02-002 | H8: 鋼筋SD420W | J8: 土木 | K8: 03210 鋼筋 | M8: 博大 | N8: =IF(P8="","",P8-60) -> 45793 | P8: 45853 | Q8: =IF(N8="","",IF(U8<>"","",IF(AND(U8="",N8-TODAY()<=60),N8-TODAY(),""))) | R8: =IF(AND(ISNUMBER(N8),ISNUMBER(U8)),N8-U8,"") -> 36 | S8: 核定 | T8: 0-A | U8: 45757 | V8: 鼎水資字第 1140000305 號函 | W8: 45762 | X8: 艾奕康新竹海淡監字第1140415-1 號 | Y8: 審查同意 | Z8: 45765 | AA8: 艾奕康水字第1140012844號 | AB8: =IF(Z8="","",IF(Y8="檢退","檢退",IF(Y8="審查同意","審定","檢退"))) -> 審定 | AC8: 45775 | AD8: 水北多字第11453040750號 | AE8: =IF(AC8="","",IF(AB8="檢退","請修正",IF(AB8="請備查","備查",IF(AB8="審定","核定","請修正")))) -> 核定
E9: 5 | F9: S-SB02-002 | H9: 鋼筋SD280 | J9: 土木 | K9: 03210 鋼筋 | M9: 益聯 | N9: =IF(P9="","",P9-60) -> 45793 | P9: 45853 | Q9: =IF(N9="","",IF(U9<>"","",IF(AND(U9="",N9-TODAY()<=60),N9-TODAY(),""))) | R9: =IF(AND(ISNUMBER(N9),ISNUMBER(U9)),N9-U9,"") -> 31 | S9: 核定 | T9: 1-A | U9: 45762 | V9: 鼎水資字第1140000320號 | W9: 45764 | X9: 艾奕康新竹海淡監字第1140417-1 號 | Y9: 審查同意 | Z9: 45765 | AA9: 艾奕康水字第1140012843號 | AB9: =IF(Z9="","",IF(Y9="檢退","檢退",IF(Y9="審查同意","審定","檢退"))) -> 審定 | AC9: 45775 | AD9: 水北多字第11453040750號 | AE9: =IF(AC9="","",IF(AB9="檢退","請修正",IF(AB9="請備查","備查",IF(AB9="審定","核定","請修正")))) -> 核定
E10: 6 | F10: S-SB02-002 | H10: 鋼筋SD280W | J10: 土木 | K10: 03210 鋼筋 | M10: 益聯 | N10: =IF(P10="","",P10-60) -> 45793 | P10: 45853 | Q10: =IF(N10="","",IF(U10<>"","",IF(AND(U10="",N10-TODAY()<=60),N10-TODAY(),""))) | R10: =IF(AND(ISNUMBER(N10),ISNUMBER(U10)),N10-U10,"") -> 31 | S10: 核定 | T10: 1-A | U10: 45762 | V10: 鼎水資字第1140000320號 | W10: 45764 | X10: 艾奕康新竹海淡監字第1140417-1 號 | Y10: 審查同意 | Z10: 45765 | AA10: 艾奕康水字第1140012843號 | AB10: =IF(Z10="","",IF(Y10="檢退","檢退",IF(Y10="審查同意","審定","檢退"))) -> 審定 | AC10: 45775 | AD10: 水北多字第11453040750號 | AE10: =IF(AC10="","",IF(AB10="檢退","請修正",IF(AB10="請備查","備查",IF(AB10="審定","核定","請修正")))) -> 核定
E11: 7 | F11: S-SB02-002 | H11: 鋼筋SD420W | J11: 土木 | K11: 03210 鋼筋 | M11: 益聯 | N11: =IF(P11="","",P11-60) -> 45793 | P11: 45853 | Q11: =IF(N11="","",IF(U11<>"","",IF(AND(U11="",N11-TODAY()<=60),N11-TODAY(),""))) | R11: =IF(AND(ISNUMBER(N11),ISNUMBER(U11)),N11-U11,"") -> 31 | S11: 核定 | T11: 1-A | U11: 45762 | V11: 鼎水資字第1140000320號 | W11: 45764 | X11: 艾奕康新竹海淡監字第1140417-1 號 | Y11: 審查同意 | Z11: 45765 | AA11: 艾奕康水字第1140012843號 | AB11: =IF(Z11="","",IF(Y11="檢退","檢退",IF(Y11="審查同意","審定","檢退"))) -> 審定 | AC11: 45775 | AD11: 水北多字第11453040750號 | AE11: =IF(AC11="","",IF(AB11="檢退","請修正",IF(AB11="請備查","備查",IF(AB11="審定","核定","請修正")))) -> 核定
E12: 8 | F12: S-SB12-005 | H12: 鋼筋SD280 | J12: 土木 | K12: 03210 鋼筋 | M12: 海光 | N12: =IF(P12="","",P12-60) -> 45793 | P12: 45853 | Q12: =IF(N12="","",IF(U12<>"","",IF(AND(U12="",N12-TODAY()<=60),N12-TODAY(),""))) | R12: =IF(AND(ISNUMBER(N12),ISNUMBER(U12)),N12-U12,"") -> 1 | S12: 核定 | T12: 0-A | U12: 45792 | V12: 鼎水 資字第1140000440號 | W12: 45793 | X12: 艾奕康新竹海淡監字第1140516-2 號 | Y12: 審查同意 | Z12: 45797 | AA12: 艾奕康水字第1140016229號 | AB12: =IF(Z12="","",IF(Y12="檢退","檢退",IF(Y12="審查同意","審定","檢退"))) -> 審定 | AC12: 45799 | AD12: 水北多字第11453053790號 | AE12: =IF(AC12="","",IF(AB12="檢退","請修正",IF(AB12="請備查","備查",IF(AB12="審定","核定","請修正")))) -> 核定
E13: 9 | F13: S-SB12-005 | H13: 鋼筋SD280W | J13: 土木 | K13: 03210 鋼筋 | M13: 海光 | N13: =IF(P13="","",P13-60) -> 45793 | P13: 45853 | Q13: =IF(N13="","",IF(U13<>"","",IF(AND(U13="",N13-TODAY()<=60),N13-TODAY(),""))) | R13: =IF(AND(ISNUMBER(N13),ISNUMBER(U13)),N13-U13,"") -> 1 | S13: 核定 | T13: 0-A | U13: 45792 | V13: 鼎水 資字第1140000440號 | W13: 45793 | X13: 艾奕康新竹海淡監字第1140516-2 號 | Y13: 審查同意 | Z13: 45797 | AA13: 艾奕康水字第1140016229號 | AB13: =IF(Z13="","",IF(Y13="檢退","檢退",IF(Y13="審查同意","審定","檢退"))) -> 審定 | AC13: 45799 | AD13: 水北多字第11453053790號 | AE13: =IF(AC13="","",IF(AB13="檢退","請修正",IF(AB13="請備查","備查",IF(AB13="審定","核定","請修正")))) -> 核定
E14: 10 | F14: S-SB12-005 | H14: 鋼筋SD420W | J14: 土木 | K14: 03210 鋼筋 | M14: 海光 | N14: =IF(P14="","",P14-60) -> 45793 | P14: 45853 | Q14: =IF(N14="","",IF(U14<>"","",IF(AND(U14="",N14-TODAY()<=60),N14-TODAY(),""))) | R14: =IF(AND(ISNUMBER(N14),ISNUMBER(U14)),N14-U14,"") -> 1 | S14: 核定 | T14: 0-A | U14: 45792 | V14: 鼎水 資字第1140000440號 | W14: 45793 | X14: 艾奕康新竹海淡監字第1140516-2 號 | Y14: 審查同意 | Z14: 45797 | AA14: 艾奕康水字第1140016229號 | AB14: =IF(Z14="","",IF(Y14="檢退","檢退",IF(Y14="審查同意","審定","檢退"))) -> 審定 | AC14: 45799 | AD14: 水北多字第11453053790號 | AE14: =IF(AC14="","",IF(AB14="檢退","請修正",IF(AB14="請備查","備查",IF(AB14="審定","核定","請修正")))) -> 核定
E15: 11 | F15: S-SB02-007 | H15: 鋼筋SD280 | J15: 土木 | K15: 03210 鋼筋 | M15: 修緣 | N15: =IF(P15="","",P15-60) -> 45793 | P15: 45853 | Q15: =IF(N15="","",IF(U15<>"","",IF(AND(U15="",N15-TODAY()<=60),N15-TODAY(),""))) | R15: =IF(AND(ISNUMBER(N15),ISNUMBER(U15)),N15-U15,"") -> -24 | T15: 0-A | U15: 45817 | V15: 鼎水資字第1140000538號 | W15: 45820 | X15: 艾奕康新竹海淡監字第1140612-3 號 | Y15: 審查同意 | Z15: 45825 | AA15: 艾奕康水字第1140018746號 | AB15: =IF(Z15="","",IF(Y15="檢退","檢退",IF(Y15="審查同意","審定","檢退"))) -> 審定 | AC15: 45832 | AD15: 水北多字第11453064050號 | AE15: =IF(AC15="","",IF(AB15="檢退","請修正",IF(AB15="請備查","備查",IF(AB15="審定","核定","請修正")))) -> 核定
S16: 修正 | T16: 1-A | U16: 46045 | V16: 鼎水資字第1150000120號 | W16: 115/2/23 | X16: 艾奕康水字第1150003031號 | Y16: 檢退
E17: 12 | F17: S-SB02-007 | H17: 鋼筋SD280W | J17: 土木 | K17: 03210 鋼筋 | M17: 修緣 | N17: =IF(P17="","",P17-60) -> 45793 | P17: 45853 | Q17: =IF(N17="","",IF(U17<>"","",IF(AND(U17="",N17-TODAY()<=60),N17-TODAY(),""))) | R17: =IF(AND(ISNUMBER(N17),ISNUMBER(U17)),N17-U17,"") -> -24 | T17: 0-A | U17: 45817 | V17: 鼎水資字第1140000538號 | W17: 45820 | X17: 艾奕康新竹海淡監字第1140612-3 號 | Y17: 審查同意 | Z17: 45825 | AA17: 艾奕康水字第1140018746號 | AB17: =IF(Z17="","",IF(Y17="檢退","檢退",IF(Y17="審查同意","審定","檢退"))) -> 審定 | AC17: 45832 | AD17: 水北多字第11453064050號 | AE17: =IF(AC17="","",IF(AB17="檢退","請修正",IF(AB17="請備查","備查",IF(AB17="審定","核定","請修正")))) -> 核定
S18: 修正 | T18: 1-A | U18: 46045 | V18: 鼎水資字第1150000120號 | W18: 115/2/23 | X18: 艾奕康水字第1150003031號 | Y18: 檢退
E19: 13 | F19: S-SB02-007 | H19: 鋼筋SD420 | J19: 土木 | K19: 03210 鋼筋 | M19: 修緣 | N19: =IF(P19="","",P19-60) -> 45793 | P19: 45853 | Q19: =IF(N19="","",IF(U19<>"","",IF(AND(U19="",N19-TODAY()<=60),N19-TODAY(),""))) | R19: =IF(AND(ISNUMBER(N19),ISNUMBER(U19)),N19-U19,"") -> -24 | T19: 0-A | U19: 45817 | V19: 鼎水資字第1140000538號 | W19: 45820 | X19: 艾奕康新竹海淡監字第1140612-3 號 | Y19: 審查同意 | Z19: 45825 | AA19: 艾奕康水字第1140018746號 | AB19: =IF(Z19="","",IF(Y19="檢退","檢退",IF(Y19="審查同意","審定","檢退"))) -> 審定 | AC19: 45832 | AD19: 水北多字第11453064050號 | AE19: =IF(AC19="","",IF(AB19="檢退","請修正",IF(AB19="請備查","備查",IF(AB19="審定","核定","請修正")))) -> 核定
S20: 修正 | T20: 1-A | U20: 46045 | V20: 鼎水資字第1150000120號 | W20: 115/2/23 | X20: 艾奕康水字第1150003031號 | Y20: 檢退
E21: 14 | F21: S-SB02-007 | H21: 鋼筋SD420W | J21: 土木 | K21: 03210 鋼筋 | M21: 修緣 | N21: =IF(P21="","",P21-60) -> 45793 | P21: 45853 | Q21: =IF(N21="","",IF(U21<>"","",IF(AND(U21="",N21-TODAY()<=60),N21-TODAY(),""))) | R21: =IF(AND(ISNUMBER(N21),ISNUMBER(U21)),N21-U21,"") -> -24 | T21: 0-A | U21: 45817 | V21: 鼎水資字第1140000538號 | W21: 45820 | X21: 艾奕康新竹海淡監字第1140612-3 號 | Y21: 審查同意 | Z21: 45825 | AA21: 艾奕康水字第1140018746號 | AB21: =IF(Z21="","",IF(Y21="檢退","檢退",IF(Y21="審查同意","審定","檢退"))) -> 審定 | AC21: 45832 | AD21: 水北多字第11453064050號 | AE21: =IF(AC21="","",IF(AB21="檢退","請修正",IF(AB21="請備查","備查",IF(AB21="審定","核定","請修正")))) -> 核定
S22: 修正 | T22: 1-A | U22: 46045 | V22: 鼎水資字第1150000120號 | W22: 115/2/23 | X22: 艾奕康水字第1150003031號 | Y22: 檢退
E23: 15 | F23: S-SB34-018 | H23: 光面鋼筋材料 | J23: 土木 | K23: 03210 鋼筋 | M23: 廣霖鋼鐵 | S23: 核定 | T23: 0-A | U23: 45925 | V23: 鼎水資字第1140001038號 | W23: 45937 | X23: 艾奕康新竹海淡監字第1141007-2 號 | Y23: 審查同意 | Z23: 45944 | AA23: 艾奕康水字第1140029720號 | AB23: =IF(Z23="","",IF(Y23="檢退","檢退",IF(Y23="審查同意","審定","檢退"))) -> 審定 | AC23: 45947 | AD23: 水北多字第11453113020號 | AE23: =IF(AC23="","",IF(AB23="檢退","請修正",IF(AB23="請備查","備查",IF(AB23="審定","核定","請修正")))) -> 核定
E24: 16 | F24: S-SB47-31 | H24: 鋼筋SD280 | J24: 土木 | K24: 03210 鋼筋 | M24: 京品 | N24: =IF(P24="","",P24-60) | O24: =IF(P24="","",P24-30) | Q24: =IF(N24="","",IF(U24<>"","",IF(AND(U24="",N24-TODAY()<=60),N24-TODAY(),""))) | R24: =IF(AND(ISNUMBER(N24),ISNUMBER(U24)),N24-U24,"") | T24: 0-A | U24: 46010 | V24: 鼎水資字第1140001542號 | W24: 46386 | X24: 艾奕康水字第1140035884號 | Y24: 審查同意 | Z24: 46028 | AA24: 艾奕康水字第1140036516號 | AB24: 審定 | AC24: 46056 | AD24: 水北多字第11522005540號 | AE24: =IF(AC24="","",IF(AB24="檢退","請修正",IF(AB24="請備查","備查",IF(AB24="審定","核定","請修正")))) -> 核定 | AF24: =IF(MOD(ROW()-5,3)<>0,"", IF(COUNTA(U24:U26,V24:V26,W24:W26,X24:X26,Y24:Y26,Z24:Z26,AA24:AA26,AB24:AB26,AC24:AC26,AD24:AD26,AE24:AE26)=0,"", IF(COUNTIF(U24:U26,"*核定*")+COUNTIF(V24:V26,"*核定*")+COUNTIF(W24:W26,"*核定*")+COUNTIF(X24:X26,"*核定*")+COUNTIF(Y24:Y26,"*核定*")+COUNTIF(Z24:Z26,"*核定*")+COUNTIF(AA24:AA26,"*核定*")+COUNTIF(AB24:AB26,"*核定*")+COUNTIF(AC24:AC26,"*核定*")+COUNTIF(AD24:AD26,"*核定*")+COUNTIF(AE24:AE26,"*核定*")>0,"核定", IF(COUNTIF(Z24:Z26,"*檢退*")>0,"檢退", IF(COUNTIF(Z24:Z26,"*審查同意*")>0,"審查同意", IF(COUNTIF(AA24:AA26,"*審定*")+COUNTIF(AB24:AB26,"*審定*")+COUNTIF(AC24:AC26,"*審定*")>0,"審定", IF(COUNTIF(U24:U26,"*核定中*")+COUNTIF(V24:V26,"*核定中*")+COUNTIF(W24:W26,"*核定中*")+COUNTIF(X24:X26,"*核定中*")+COUNTIF(Y24:Y26,"*核定中*")+COUNTIF(Z24:Z26,"*核定中*")+COUNTIF(AA24:AA26,"*核定中*")+COUNTIF(AB24:AB26,"*核定中*")+COUNTIF(AC24:AC26,"*核定中*")+COUNTIF(AD24:AD26,"*核定中*")+COUNTIF(AE24:AE26,"*核定中*")>0,"核定中","")))))))
Q25: =IF(N25="","",IF(U25<>"","",IF(AND(U25="",N25-TODAY()<=60),N25-TODAY(),""))) | R25: =IF(AND(ISNUMBER(N25),ISNUMBER(U25)),N25-U25,"") | S25: 核定 | T25: 1-A | U25: 46056 | V25: 鼎水資字第1150000194號 | W25: 46097 | X25: 艾奕康水字第1150005000號 | Y25: 審查同意 | Z25: 46097 | AA25: 艾奕康水字第1150005000號 | AB25: 審定 | AC25: 115/3/24 | AD25: 北水多字第11522013680號 | AE25: 核定
Q26: =IF(N26="","",IF(U26<>"","",IF(AND(U26="",N26-TODAY()<=60),N26-TODAY(),""))) | R26: =IF(AND(ISNUMBER(N26),ISNUMBER(U26)),N26-U26,"") | AB26: =IF(Z26="","",IF(Y26="檢退","檢退",IF(Y26="審查同意","審定","檢退"))) | AE26: =IF(AC26="","",IF(AB26="檢退","請修正",IF(AB26="請備查","備查",IF(AB26="審定","核定","請修正"))))
E27: 17 | F27: S-SB47-31 | H27: 鋼筋SD280W | J27: 土木 | K27: 03210 鋼筋 | M27: 京品 | N27: =IF(P27="","",P27-60) | O27: =IF(P27="","",P27-30) | Q27: =IF(N27="","",IF(U27<>"","",IF(AND(U27="",N27-TODAY()<=60),N27-TODAY(),""))) | R27: =IF(AND(ISNUMBER(N27),ISNUMBER(U27)),N27-U27,"") | T27: 0-A | U27: 46010 | V27: 鼎水資字第1140001542號 | W27: 46386 | X27: 艾奕康水字第1140035884號 | Y27: 審查同意 | Z27: 46028 | AA27: 艾奕康水字第1140036516號 | AB27: 審定 | AC27: 46056 | AD27: 水北多字第11522005540號 | AE27: =IF(AC27="","",IF(AB27="檢退","請修正",IF(AB27="請備查","備查",IF(AB27="審定","核定","請修正")))) -> 核定 | AF27: =IF(MOD(ROW()-5,3)<>0,"", IF(COUNTA(U27:U29,V27:V29,W27:W29,X27:X29,Y27:Y29,Z27:Z29,AA27:AA29,AB27:AB29,AC27:AC29,AD27:AD29,AE27:AE29)=0,"", IF(COUNTIF(U27:U29,"*核定*")+COUNTIF(V27:V29,"*核定*")+COUNTIF(W27:W29,"*核定*")+COUNTIF(X27:X29,"*核定*")+COUNTIF(Y27:Y29,"*核定*")+COUNTIF(Z27:Z29,"*核定*")+COUNTIF(AA27:AA29,"*核定*")+COUNTIF(AB27:AB29,"*核定*")+COUNTIF(AC27:AC29,"*核定*")+COUNTIF(AD27:AD29,"*核定*")+COUNTIF(AE27:AE29,"*核定*")>0,"核定", IF(COUNTIF(Z27:Z29,"*檢退*")>0,"檢退", IF(COUNTIF(Z27:Z29,"*審查同意*")>0,"審查同意", IF(COUNTIF(AA27:AA29,"*審定*")+COUNTIF(AB27:AB29,"*審定*")+COUNTIF(AC27:AC29,"*審定*")>0,"審定", IF(COUNTIF(U27:U29,"*核定中*")+COUNTIF(V27:V29,"*核定中*")+COUNTIF(W27:W29,"*核定中*")+COUNTIF(X27:X29,"*核定中*")+COUNTIF(Y27:Y29,"*核定中*")+COUNTIF(Z27:Z29,"*核定中*")+COUNTIF(AA27:AA29,"*核定中*")+COUNTIF(AB27:AB29,"*核定中*")+COUNTIF(AC27:AC29,"*核定中*")+COUNTIF(AD27:AD29,"*核定中*")+COUNTIF(AE27:AE29,"*核定中*")>0,"核定中","")))))))
Q28: =IF(N28="","",IF(U28<>"","",IF(AND(U28="",N28-TODAY()<=60),N28-TODAY(),""))) | R28: =IF(AND(ISNUMBER(N28),ISNUMBER(U28)),N28-U28,"") | S28: 核定 | T28: 1-A | U28: 46056 | V28: 鼎水資字第1150000194號 | W28: 46097 | X28: 艾奕康水字第1150005000號 | Y28: 審查同意 | Z28: 46097 | AA28: 艾奕康水字第1150005000號 | AB28: 審定 | AC28: 115/3/24 | AD28: 北水多字第11522013680號 | AE28: 核定
Q29: =IF(N29="","",IF(U29<>"","",IF(AND(U29="",N29-TODAY()<=60),N29-TODAY(),""))) | R29: =IF(AND(ISNUMBER(N29),ISNUMBER(U29)),N29-U29,"") | AB29: =IF(Z29="","",IF(Y29="檢退","檢退",IF(Y29="審查同意","審定","檢退"))) | AE29: =IF(AC29="","",IF(AB29="檢退","請修正",IF(AB29="請備查","備查",IF(AB29="審定","核定","請修正"))))
E30: 18 | F30: S-SB47-31 | H30: 鋼筋SD420 | J30: 土木 | K30: 03210 鋼筋 | M30: 京品 | N30: =IF(P30="","",P30-60) | O30: =IF(P30="","",P30-30) | Q30: =IF(N30="","",IF(U30<>"","",IF(AND(U30="",N30-TODAY()<=60),N30-TODAY(),""))) | R30: =IF(AND(ISNUMBER(N30),ISNUMBER(U30)),N30-U30,"") | T30: 0-A | U30: 46010 | V30: 鼎水資字第1140001542號 | W30: 46386 | X30: 艾奕康水字第1140035884號 | Y30: 審查同意 | Z30: 46028 | AA30: 艾奕康水字第1140036516號 | AB30: 審定 | AC30: 46056 | AD30: 水北多字第11522005540號 | AE30: =IF(AC30="","",IF(AB30="檢退","請修正",IF(AB30="請備查","備查",IF(AB30="審定","核定","請修正")))) -> 核定 | AF30: =IF(MOD(ROW()-5,3)<>0,"", IF(COUNTA(U30:U32,V30:V32,W30:W32,X30:X32,Y30:Y32,Z30:Z32,AA30:AA32,AB30:AB32,AC30:AC32,AD30:AD32,AE30:AE32)=0,"", IF(COUNTIF(U30:U32,"*核定*")+COUNTIF(V30:V32,"*核定*")+COUNTIF(W30:W32,"*核定*")+COUNTIF(X30:X32,"*核定*")+COUNTIF(Y30:Y32,"*核定*")+COUNTIF(Z30:Z32,"*核定*")+COUNTIF(AA30:AA32,"*核定*")+COUNTIF(AB30:AB32,"*核定*")+COUNTIF(AC30:AC32,"*核定*")+COUNTIF(AD30:AD32,"*核定*")+COUNTIF(AE30:AE32,"*核定*")>0,"核定", IF(COUNTIF(Z30:Z32,"*檢退*")>0,"檢退", IF(COUNTIF(Z30:Z32,"*審查同意*")>0,"審查同意", IF(COUNTIF(AA30:AA32,"*審定*")+COUNTIF(AB30:AB32,"*審定*")+COUNTIF(AC30:AC32,"*審定*")>0,"審定", IF(COUNTIF(U30:U32,"*核定中*")+COUNTIF(V30:V32,"*核定中*")+COUNTIF(W30:W32,"*核定中*")+COUNTIF(X30:X32,"*核定中*")+COUNTIF(Y30:Y32,"*核定中*")+COUNTIF(Z30:Z32,"*核定中*")+COUNTIF(AA30:AA32,"*核定中*")+COUNTIF(AB30:AB32,"*核定中*")+COUNTIF(AC30:AC32,"*核定中*")+COUNTIF(AD30:AD32,"*核定中*")+COUNTIF(AE30:AE32,"*核定中*")>0,"核定中","")))))))
Q31: =IF(N31="","",IF(U31<>"","",IF(AND(U31="",N31-TODAY()<=60),N31-TODAY(),""))) | R31: =IF(AND(ISNUMBER(N31),ISNUMBER(U31)),N31-U31,"") | S31: 核定 | T31: 1-A | U31: 46056 | V31: 鼎水資字第1150000194號 | W31: 46097 | X31: 艾奕康水字第1150005000號 | Y31: 審查同意 | Z31: 46097 | AA31: 艾奕康水字第1150005000號 | AB31: 審定 | AC31: 115/3/24 | AD31: 北水多字第11522013680號 | AE31: 核定
Q32: =IF(N32="","",IF(U32<>"","",IF(AND(U32="",N32-TODAY()<=60),N32-TODAY(),""))) | R32: =IF(AND(ISNUMBER(N32),ISNUMBER(U32)),N32-U32,"") | AB32: =IF(Z32="","",IF(Y32="檢退","檢退",IF(Y32="審查同意","審定","檢退"))) | AE32: =IF(AC32="","",IF(AB32="檢退","請修正",IF(AB32="請備查","備查",IF(AB32="審定","核定","請修正"))))
E33: 19 | F33: S-SB47-31 | H33: 鋼筋SD420W | J33: 土木 | K33: 03210 鋼筋 | M33: 京品 | N33: =IF(P33="","",P33-60) | O33: =IF(P33="","",P33-30) | Q33: =IF(N33="","",IF(U33<>"","",IF(AND(U33="",N33-TODAY()<=60),N33-TODAY(),""))) | R33: =IF(AND(ISNUMBER(N33),ISNUMBER(U33)),N33-U33,"") | T33: 0-A | U33: 46010 | V33: 鼎水資字第1140001542號 | W33: 46386 | X33: 艾奕康水字第1140035884號 | Y33: 審查同意 | Z33: 46028 | AA33: 艾奕康水字第1140036516號 | AB33: 審定 | AC33: 46056 | AD33: 水北多字第11522005540號 | AE33: =IF(AC33="","",IF(AB33="檢退","請修正",IF(AB33="請備查","備查",IF(AB33="審定","核定","請修正")))) -> 核定 | AF33: =IF(MOD(ROW()-5,3)<>0,"", IF(COUNTA(U33:U35,V33:V35,W33:W35,X33:X35,Y33:Y35,Z33:Z35,AA33:AA35,AB33:AB35,AC33:AC35,AD33:AD35,AE33:AE35)=0,"", IF(COUNTIF(U33:U35,"*核定*")+COUNTIF(V33:V35,"*核定*")+COUNTIF(W33:W35,"*核定*")+COUNTIF(X33:X35,"*核定*")+COUNTIF(Y33:Y35,"*核定*")+COUNTIF(Z33:Z35,"*核定*")+COUNTIF(AA33:AA35,"*核定*")+COUNTIF(AB33:AB35,"*核定*")+COUNTIF(AC33:AC35,"*核定*")+COUNTIF(AD33:AD35,"*核定*")+COUNTIF(AE33:AE35,"*核定*")>0,"核定", IF(COUNTIF(Z33:Z35,"*檢退*")>0,"檢退", IF(COUNTIF(Z33:Z35,"*審查同意*")>0,"審查同意", IF(COUNTIF(AA33:AA35,"*審定*")+COUNTIF(AB33:AB35,"*審定*")+COUNTIF(AC33:AC35,"*審定*")>0,"審定", IF(COUNTIF(U33:U35,"*核定中*")+COUNTIF(V33:V35,"*核定中*")+COUNTIF(W33:W35,"*核定中*")+COUNTIF(X33:X35,"*核定中*")+COUNTIF(Y33:Y35,"*核定中*")+COUNTIF(Z33:Z35,"*核定中*")+COUNTIF(AA33:AA35,"*核定中*")+COUNTIF(AB33:AB35,"*核定中*")+COUNTIF(AC33:AC35,"*核定中*")+COUNTIF(AD33:AD35,"*核定中*")+COUNTIF(AE33:AE35,"*核定中*")>0,"核定中","")))))))
Q34: =IF(N34="","",IF(U34<>"","",IF(AND(U34="",N34-TODAY()<=60),N34-TODAY(),""))) | R34: =IF(AND(ISNUMBER(N34),ISNUMBER(U34)),N34-U34,"") | S34: 核定 | T34: 1-A | U34: 46056 | V34: 鼎水資字第1150000194號 | W34: 46097 | X34: 艾奕康水字第1150005000號 | Y34: 審查同意 | Z34: 46097 | AA34: 艾奕康水字第1150005000號 | AB34: 審定 | AC34: 115/3/24 | AD34: 北水多字第11522013680號 | AE34: 核定
Q35: =IF(N35="","",IF(U35<>"","",IF(AND(U35="",N35-TODAY()<=60),N35-TODAY(),""))) | R35: =IF(AND(ISNUMBER(N35),ISNUMBER(U35)),N35-U35,"") | AB35: =IF(Z35="","",IF(Y35="檢退","檢退",IF(Y35="審查同意","審定","檢退"))) | AE35: =IF(AC35="","",IF(AB35="檢退","請修正",IF(AB35="請備查","備查",IF(AB35="審定","核定","請修正"))))
E36: 20 | F36: S-SB55-039 | H36: 鋼筋SD280 | J36: 土木 | K36: 03210 鋼筋 | M36: 豐興 | O36: =IF(P36="","",P36-30) | Q36: =IF(N36="","",IF(U36<>"","",IF(AND(U36="",N36-TODAY()<=60),N36-TODAY(),""))) | R36: =IF(AND(ISNUMBER(N36),ISNUMBER(U36)),N36-U36,"") | S36: 核定 | T36: 0-A | U36: 46058 | V36: 鼎水資字第1150000205號 | W36: 46097 | X36: 艾奕康水字第1150005046號 | Y36: 審查同意 | Z36: 46097 | AA36: 艾奕康水字第1150005046號 | AB36: 審定 | AC36: 115/3/24 | AD36: 北水多字第11522013680號 | AE36: 核定
Q37: =IF(N37="","",IF(U37<>"","",IF(AND(U37="",N37-TODAY()<=60),N37-TODAY(),""))) | R37: =IF(AND(ISNUMBER(N37),ISNUMBER(U37)),N37-U37,"") | AB37: =IF(Z37="","",IF(Y37="檢退","檢退",IF(Y37="審查同意","審定","檢退")))
Q38: =IF(N38="","",IF(U38<>"","",IF(AND(U38="",N38-TODAY()<=60),N38-TODAY(),""))) | R38: =IF(AND(ISNUMBER(N38),ISNUMBER(U38)),N38-U38,"") | AB38: =IF(Z38="","",IF(Y38="檢退","檢退",IF(Y38="審查同意","審定","檢退")))
E39: 21 | F39: S-SB55-039 | H39: 鋼筋SD280W | J39: 土木 | K39: 03210 鋼筋 | M39: 豐興 | O39: =IF(P39="","",P39-30) | Q39: =IF(N39="","",IF(U39<>"","",IF(AND(U39="",N39-TODAY()<=60),N39-TODAY(),""))) | R39: =IF(AND(ISNUMBER(N39),ISNUMBER(U39)),N39-U39,"") | S39: 核定 | T39: 0-A | U39: 46058 | V39: 鼎水資字第1150000205號 | W39: 46097 | X39: 艾奕康水字第1150005046號 | Y39: 審查同意 | Z39: 46097 | AA39: 艾奕康水字第1150005046號 | AB39: 審定 | AC39: 115/3/24 | AD39: 北水多字第11522013680號 | AE39: 核定
Q40: =IF(N40="","",IF(U40<>"","",IF(AND(U40="",N40-TODAY()<=60),N40-TODAY(),""))) | R40: =IF(AND(ISNUMBER(N40),ISNUMBER(U40)),N40-U40,"") | AB40: =IF(Z40="","",IF(Y40="檢退","檢退",IF(Y40="審查同意","審定","檢退")))
...

Sheet 10-3取排水(宏華)
A2: 項次 | B2: 編碼 | C2: 文件 | D2: 預定送審 (進場前60天) | E2: 預定廠驗 (進場前30天) | F2: 類別 | G2: 規範 | H2: 圖面 | I2: 廠商 | J2: 預定進場 | K2: 送審預警天數(60天內才顯示) | L2: 送審延遲 | M2: 程序 | N2: 版次 | O2: 審查情形 | Z2: 備註
K3: 辦理預警 | O3: 統包商 | Q3: 監造 | T3: 專管 | W3: 機關(北水分署)
O4: 日期 | P4: 文號 | Q4: 日期 | R4: 文號 | S4: 結果 | T4: 日期 | U4: 文號 | V4: 結果 | W4: 日期 | X4: 文號 | Y4: 結果
A5: 1 | B5: S-SB31-015 | C5: 塊石及礫石材料-國正 | D5: =IF(J5="","",J5-60) -> 45912 | E5: =IF(J5="","",J5-30) -> 45942 | G5: 施工規範第02381章 | H5: B-002089-HHC-MW-019-DD-142、242 | I5: 國正工程 | J5: 45972 | K5: =IF(D5="","",IF(O5<>"","",IF(AND(O5="",D5-TODAY()<=60),D5-TODAY(),""))) | L5: =IF(COUNT(D5, O5)=2, D5-O5, "") -> 25 | N5: 0-A | O5: 45887 | P5: 宏海淡工字第114081102號 | Q5: 45897 | R5: 艾奕康水字第1140021973號 | S5: 檢退 | V5: =IF(T5="","",IF(S5="檢退","檢退",IF(S5="審查同意","審定","檢退")))
D6: =Q5+7 -> 45904 | K6: =IF(D6="","",IF(O6<>"","",IF(AND(O6="",D6-TODAY()<=60),D6-TODAY(),""))) | L6: =IF(COUNT(D6, O6)=2, D6-O6, "") -> -12 | M6: 核定 | N6: 0-B | O6: 45916 | P6: 宏海淡工字第114091106號 | Q6: 45919 | R6: 艾奕康新竹海淡監字第1140919-3 號 | S6: 審查同意 | T6: 45926 | U6: 艾奕康水字第1140028399號 | V6: 審定 | W6: 45931 | X6: 水北多字第11453107360號 | Y6: 核定
K7: =IF(D7="","",IF(O7<>"","",IF(AND(O7="",D7-TODAY()<=60),D7-TODAY(),""))) | L7: =IF(COUNT(D7, O7)=2, D7-O7, "")
A8: =A5+1 -> 2 | B8: S-SB25-008 | C8: HDPE管-大地昌 | D8: =IF(J8="","",J8-60) -> 45810 | E8: =IF(J8="","",J8-30) -> 45840 | G8: 施工規範第15226章 | I8: 大地昌 | J8: 45870 | K8: =IF(D8="","",IF(O8<>"","",IF(AND(O8="",D8-TODAY()<=60),D8-TODAY(),""))) | L8: =IF(COUNT(D8, O8)=2, D8-O8, "") -> -11 | N8: 0-A | O8: 45821 | P8: 宏海淡工字第114061102號 | Q8: 45834 | R8: 艾奕康水字 第1140016974號 | S8: 審退 | V8: =IF(T8="","",IF(S8="檢退","檢退",IF(S8="審查同意","審定","檢退")))
K9: =IF(D9="","",IF(O9<>"","",IF(AND(O9="",D9-TODAY()<=60),D9-TODAY(),""))) | L9: =IF(COUNT(D9, O9)=2, D9-O9, "") | M9: 核定 | N9: 0-B | O9: 45839 | P9: 宏海淡工字 第114071101號 | Q9: 45848 | R9: 艾奕康新竹海淡監字第1140710-3 號 | S9: 審查同意 | T9: 45852 | U9: 艾奕康水字第1140021290號 | V9: =IF(T9="","",IF(S9="檢退","檢退",IF(S9="審查同意","審定","檢退"))) -> 審定 | W9: 45862 | X9: 水北多字第11422023610號 | Y9: 核定
L10: =IF(COUNT(D10, O10)=2, D10-O10, "")
A11: =A8+1 -> 3 | B11: S-SB26-009 | C11: HDPE管法蘭片 | D11: =IF(J11="","",J11-60) -> 45902 | E11: =IF(J11="","",J11-30) -> 45932 | G11: 施工規範第15226章 | I11: 三永裕 | J11: 45962 | K11: =IF(D11="","",IF(O11<>"","",IF(AND(O11="",D11-TODAY()<=60),D11-TODAY(),""))) | L11: =IF(COUNT(D11, O11)=2, D11-O11, "") -> 1 | N11: 0-A | O11: 45901 | P11: 宏海淡工字第114091101號 | Q11: 45909 | R11: 艾奕康水字第1140025014號 | S11: 檢退-限9/16提送 | V11: =IF(T11="","",IF(S11="檢退","檢退",IF(S11="審查同意","審定","檢退")))
D12: 45916 | K12: =IF(D12="","",IF(O12<>"","",IF(AND(O12="",D12-TODAY()<=60),D12-TODAY(),""))) | L12: =IF(COUNT(D12, O12)=2, D12-O12, "") -> 0 | N12: 0-B | O12: 45916 | P12: 宏海淡工字第114091107號 | Q12: 45919 | R12: 艾奕康水字第1140025040號 | S12: 檢退 | V12: =IF(T12="","",IF(S12="檢退","檢退",IF(S12="審查同意","審定","檢退")))
D13: =Q11+7 -> 45916 | K13: =IF(D13="","",IF(O13<>"","",IF(AND(O13="",D13-TODAY()<=60),D13-TODAY(),""))) | L13: =IF(COUNT(D13, O13)=2, D13-O13, "") -> -27 | N13: 0-C | O13: 45943 | P13: 宏海淡工字第114101105號 | Q13: 45947 | R13: 艾奕康新竹海淡監字第1141017-1號 | S13: 審查同意 | T13: 45953 | U13: 艾奕康水字第1140030745號 | V13: =IF(T13="","",IF(S13="檢退","檢退",IF(S13="審查同意","審定","檢退"))) -> 審定 | W13: 45965 | X13: 水北多字第11422037820號
K14: =IF(D14="","",IF(O14<>"","",IF(AND(O14="",D14-TODAY()<=60),D14-TODAY(),""))) | L14: =IF(COUNT(D14, O14)=2, D14-O14, "") | M14: 核定 | N14: 1-A | O14: 45988 | P14: 宏海淡工字第114111111號 | Q14: 46007 | R14: 艾奕康水字第1140032702號 | S14: 審查同意 | T14: 46009 | U14: 艾奕康水字第1140035494號 | V14: =IF(T14="","",IF(S14="檢退","檢退",IF(S14="審查同意","審定","檢退"))) -> 審定 | W14: 46020 | X14: 水北多字第11453141120號 | Y14: 核定
A15: =A11+1 -> 4 | B15: S-SB27-010 | C15: EPDM橡膠 | D15: =IF(J15="","",J15-60) -> 45902 | E15: =IF(J15="","",J15-30) -> 45932 | G15: 施工規範第15226章 | I15: 春發科技 | J15: 45962 | K15: =IF(D15="","",IF(O15<>"","",IF(AND(O15="",D15-TODAY()<=60),D15-TODAY(),""))) | L15: =IF(COUNT(D15, O15)=2, D15-O15, "") -> -14 | N15: 0-A | O15: 45916 | P15: 宏海淡工字第114091108號 | Q15: 45922 | R15: 艾奕康水字第1140027442號 | S15: 檢退 | V15: =IF(T15="","",IF(S15="檢退","檢退",IF(S15="審查同意","審定","檢退")))
D16: =Q15+7 -> 45929 | K16: =IF(D16="","",IF(O16<>"","",IF(AND(O16="",D16-TODAY()<=60),D16-TODAY(),""))) | L16: =IF(COUNT(D16, O16)=2, D16-O16, "") -> -42 | M16: 核定 | N16: 0-B | O16: 45971 | P16: 宏海淡工字第11411105號 | Q16: 45974 | R16: 艾奕康新竹海淡監字第1141113-2 | S16: 審查同意 | T16: 45980 | U16: 艾奕康水字第1140033044號 | V16: =IF(T16="","",IF(S16="檢退","檢退",IF(S16="審查同意","審定","檢退"))) -> 審定 | W16: 45999 | X16: 水北多字第11422043110號 | Y16: 核定
K17: =IF(D17="","",IF(O17<>"","",IF(AND(O17="",D17-TODAY()<=60),D17-TODAY(),""))) | L17: =IF(COUNT(D17, O17)=2, D17-O17, "") | V17: =IF(T17="","",IF(S17="檢退","檢退",IF(S17="審查同意","審定","檢退")))
A18: =A15+1 -> 5 | B18: S-SB35-019 | C18: 礫石材料送審與供料商一新寮山石礦 | D18: =IF(J18="","",J18-60) | E18: =IF(J18="","",J18-30) | G18: 施工規範第02381章 | H18: B-002089-HHC-MW-019-DD-142、242 | I18: 新寮山 | K18: =IF(D18="","",IF(O18<>"","",IF(AND(O18="",D18-TODAY()<=60),D18-TODAY(),""))) | L18: =IF(COUNT(D18, O18)=2, D18-O18, "") | M18: 核定 | N18: 0-A | O18: 45943 | P18: 宏海淡工字第114101106號 | Q18: 45947 | R18: 艾奕康新竹海淡監字第1141017-2號 | S18: 審查同意 | T18: 45953 | U18: 艾奕康水字第1140030743號 | V18: =IF(T18="","",IF(S18="檢退","檢退",IF(S18="審查同意","審定","檢退"))) -> 審定 | W18: 45960 | X18: 水北多字第11453117090號 | Y18: 核定
K19: =IF(D19="","",IF(O19<>"","",IF(AND(O19="",D19-TODAY()<=60),D19-TODAY(),""))) | L19: =IF(COUNT(D19, O19)=2, D19-O19, "")
K20: =IF(D20="","",IF(O20<>"","",IF(AND(O20="",D20-TODAY()<=60),D20-TODAY(),""))) | L20: =IF(COUNT(D20, O20)=2, D20-O20, "") | V20: =IF(T20="","",IF(S20="檢退","檢退",IF(S20="審查同意","審定","檢退")))
A21: =A18+1 -> 6 | B21: S-SB64-048 | C21: 取排水-GFRP 管-達塑 | I21: 達塑工程 | K21: =IF(D21="","",IF(O21<>"","",IF(AND(O21="",D21-TODAY()<=60),D21-TODAY(),""))) | L21: =IF(COUNT(D21, O21)=2, D21-O21, "") | N21: 0-A | O21: 115/3/6 | P21: 宏華海淡工字第 115031111號 | Q21: 115/3/25 | R21: 艾奕康水字第1150004704號 | S21: 檢退
K22: =IF(D22="","",IF(O22<>"","",IF(AND(O22="",D22-TODAY()<=60),D22-TODAY(),""))) | L22: =IF(COUNT(D22, O22)=2, D22-O22, "") | M22: 審查 | N22: 0-B | O22: 115/3/27 | P22: 宏海淡工字第115031125號 | V22: =IF(T22="","",IF(S22="檢退","檢退",IF(S22="審查同意","審定","檢退")))
K23: =IF(D23="","",IF(O23<>"","",IF(AND(O23="",D23-TODAY()<=60),D23-TODAY(),""))) | L23: =IF(COUNT(D23, O23)=2, D23-O23, "") | N23: 0-C | V23: =IF(T23="","",IF(S23="檢退","檢退",IF(S23="審查同意","審定","檢退")))
A24: =A21+1 -> 7 | B24: S-SB56-040 | C24: 取水頭-鋼製構件廠商-新樺鋼鐵 | G24: 施工規範第05122章 | I24: 新樺鋼鐵 | K24: =IF(D24="","",IF(O24<>"","",IF(AND(O24="",D24-TODAY()<=60),D24-TODAY(),""))) | L24: =IF(COUNT(D24, O24)=2, D24-O24, "") | M24: 核定 | N24: 0-A | O24: 46057 | P24: 宏海淡工字第115021101號 | Q24: 46059 | R24: 艾奕康水字第1150002561號 | S24: 審查同意 | T24: 46062 | U24: 艾奕康水字第1150003976號 | V24: 審定 | W24: 46062 | X24: 水北多字第11553016390號 | Y24: 核定
K25: =IF(D25="","",IF(O25<>"","",IF(AND(O25="",D25-TODAY()<=60),D25-TODAY(),""))) | L25: =IF(COUNT(D25, O25)=2, D25-O25, "") | N25: 0-B | V25: =IF(T25="","",IF(S25="檢退","檢退",IF(S25="審查同意","審定","檢退")))
K26: =IF(D26="","",IF(O26<>"","",IF(AND(O26="",D26-TODAY()<=60),D26-TODAY(),""))) | L26: =IF(COUNT(D26, O26)=2, D26-O26, "") | N26: 0-C | V26: =IF(T26="","",IF(S26="檢退","檢退",IF(S26="審查同意","審定","檢退")))
A27: =A24+1 -> 8 | B27: S-SB59-043 | C27: 取水頭-鋼管樁廠商-遠東鋼鐵 | G27: 施工規範第02460章 | I27: 遠東機械 | K27: =IF(D27="","",IF(O27<>"","",IF(AND(O27="",D27-TODAY()<=60),D27-TODAY(),""))) | L27: =IF(COUNT(D27, O27)=2, D27-O27, "") | M27: 審查 | N27: 0-A | O27: 115/3/6 | P27: 宏華海淡工字第 115031111號 | Q27: 115/3/25 | R27: 艾奕康水字第1150004704號 | S27: 審查同意
K28: =IF(D28="","",IF(O28<>"","",IF(AND(O28="",D28-TODAY()<=60),D28-TODAY(),""))) | L28: =IF(COUNT(D28, O28)=2, D28-O28, "") | N28: 0-B | V28: =IF(T28="","",IF(S28="檢退","檢退",IF(S28="審查同意","審定","檢退")))
K29: =IF(D29="","",IF(O29<>"","",IF(AND(O29="",D29-TODAY()<=60),D29-TODAY(),""))) | L29: =IF(COUNT(D29, O29)=2, D29-O29, "") | N29: 0-C | V29: =IF(T29="","",IF(S29="檢退","檢退",IF(S29="審查同意","審定","檢退")))
A30: =A27+1 -> 9 | B30: S-SB70-054 | C30: 取排水-海上警示燈浮 | K30: =IF(D30="","",IF(O30<>"","",IF(AND(O30="",D30-TODAY()<=60),D30-TODAY(),""))) | L30: =IF(COUNT(D30, O30)=2, D30-O30, "") | M30: 審查 | N30: 0-A | O30: 115/4/2 | P30: 宏海淡工字第115041102A號
K31: =IF(D31="","",IF(O31<>"","",IF(AND(O31="",D31-TODAY()<=60),D31-TODAY(),""))) | L31: =IF(COUNT(D31, O31)=2, D31-O31, "") | N31: 0-B | O31: 115/5/20 | P31: 宏海淡工字第115051112A號 | V31: =IF(T31="","",IF(S31="檢退","檢退",IF(S31="審查同意","審定","檢退")))
K32: =IF(D32="","",IF(O32<>"","",IF(AND(O32="",D32-TODAY()<=60),D32-TODAY(),""))) | L32: =IF(COUNT(D32, O32)=2, D32-O32, "") | N32: 0-C | V32: =IF(T32="","",IF(S32="檢退","檢退",IF(S32="審查同意","審定","檢退")))
A33: =A30+1 -> 10 | B33: S-SB68-052 | C33: 取排水-鋁陽極塊 | G33: 施工規範第05122章 | H33: B-002089-HHC-MW-019-DD-741取水頭犧牲陽極塊配置圖 | I33: 臺陽合金 | K33: =IF(D33="","",IF(O33<>"","",IF(AND(O33="",D33-TODAY()<=60),D33-TODAY(),""))) | L33: =IF(COUNT(D33, O33)=2, D33-O33, "") | M33: 審查 | N33: 0-A | O33: 115/3/27 | P33: 宏海淡工字第115031124號
K34: =IF(D34="","",IF(O34<>"","",IF(AND(O34="",D34-TODAY()<=60),D34-TODAY(),""))) | L34: =IF(COUNT(D34, O34)=2, D34-O34, "") | N34: 0-B | V34: =IF(T34="","",IF(S34="檢退","檢退",IF(S34="審查同意","審定","檢退")))
K35: =IF(D35="","",IF(O35<>"","",IF(AND(O35="",D35-TODAY()<=60),D35-TODAY(),""))) | L35: =IF(COUNT(D35, O35)=2, D35-O35, "") | N35: 0-C | V35: =IF(T35="","",IF(S35="檢退","檢退",IF(S35="審查同意","審定","檢退")))
B37: 取排水管線
B38: 應送審 | C38: =COUNTA(C5:C35) -> 10
B39: 未送審 | C39: =C38-C40-C41-C42 -> 0
B40: 已核定 | C40: =COUNTIF(M5:M35,"核定") -> 6
B41: 審查中 | C41: =COUNTIF(M5:M35,"審查") -> 4
B42: 修正中 | C42: =COUNTIF(M5:M35,"修正") -> 0

Sheet 10-4 建築裝修
C1: 新竹海水淡化廠興建及操作維護(興建部分) 材料設備送審管制總表
A2: 窗口負責人 | B2: 品管現用版本項次 | C2: 項次 | D2: 編碼 | E2: English | F2: 文件 | G2: 類別 | H2: 規範 | I2: 圖面 | J2: 廠商 | K2: 預定送審 (進場前60天) | L2: 預定廠驗 (進場前30天) | M2: 預定進場 | N2: 送審預警天數(60天內才顯示) | O2: 送審延遲 | P2: 程序 | Q2: 版次 | R2: 審查情形 | AC2: 備註
N3: 辦理預警 | R3: 統包商 | T3: 監造 | W3: 專管 | Z3: 機關(北水分署)
R4: 日期 | S4: 文號 | T4: 日期 | U4: 文號 | V4: 結果 | W4: 日期 | X4: 文號 | Y4: 結果 | Z4: 日期 | AA4: 文號 | AB4: 結果
C5: 1 | D5: S-SB53-037 | F5: 中空水泥板 | G5: 牆體/板材 | H5: 施工規範第02231 章 | I5: B-002089-NEW-AR-000-DL-013建築標準圖(13)中空水泥板 | J5: 前德實業 | K5: =IF(M5="","",M5-60) -> 46234 | L5: =IF(M5="","",M5-30) -> 46264 | M5: 46294 | N5: =IF(K5="","",IF(R5<>"","",IF(AND(R5="",K5-TODAY()<=60),K5-TODAY(),""))) | O5: =IF(AND(ISNUMBER(K5),ISNUMBER(R5)),K5-R5,"") -> 171 | P5: 核定 | Q5: 0-A | R5: 46063 | S5: 鼎水資字第1150000246號 | T5: 46097 | U5: 艾奕康水字第1150004920號 | V5: 審查同意 | W5: 46097 | X5: 艾奕康水字第1150004920號 | Y5: 審定 | Z5: 115/3/27 | AA5: 水北多字第11522014750號 | AB5: 核定
N6: =IF(K6="","",IF(R6<>"","",IF(AND(R6="",K6-TODAY()<=60),K6-TODAY(),""))) | O6: =IF(AND(ISNUMBER(K6),ISNUMBER(R6)),K6-R6,"")
N7: =IF(K7="","",IF(R7<>"","",IF(AND(R7="",K7-TODAY()<=60),K7-TODAY(),""))) | O7: =IF(AND(ISNUMBER(K7),ISNUMBER(R7)),K7-R7,"")
C8: 2 | F8: 標誌及標線 | G8: 收尾工程 | H8: 02891標誌 | K8: =IF(M8="","",M8-60) -> 46265 | L8: =IF(M8="","",M8-30) -> 46295 | M8: 46325
C11: 3 | F11: 鍍鋅鋼管可拆式欄杆/圍籬 | G11: 欄杆/踏步 | H11: 第05520章扶手及欄杆 | I11: B-002089-NEW-AR-000-DL-006 建築標準圖(6)-活動護欄/圍籬 | K11: =IF(M11="","",M11-60) -> 46173 | L11: =IF(M11="","",M11-30) -> 46203 | M11: 46233
C14: =C11+1 -> 4 | D14: S-SB52-036 | F14: FRP格柵及欄杆 | G14: 欄杆/踏步 | H14: 第05530-2章玻璃纖維強化塑膠蓋板 | I14: B-002089-NEW-AR-000-DL-007 建築標準圖(7)-蓋板 | J14: 艾柏克科技 | K14: =IF(M14="","",M14-60) -> 46204 | L14: =IF(M14="","",M14-30) -> 46234 | M14: 46264 | P14: 核定 | Q14: 0-A | R14: 46021 | S14: 鼎水資字第1140001579號 | T14: 46041 | U14: 艾奕康水字第1150002277號 | V14: 審查同意 | W14: 46041 | X14: 艾奕康水字第1150002277號 | Y14: 審查同意 | Z14: 46051 | AA14: 水北多字第11522004270號 | AB14: 核定
C17: 5 | F17: 水泥防水劑 | G17: 防水 | H17: 第 07112 章 防水水泥砂漿粉刷 | I17: 設計圖說:B-002089-NEW-AR-911-DG-038 防水隔熱詳圖一 | K17: 115/08/31 | M17: 115/08/31
C20: 6 | F20: 2mm橡化瀝青防水膜 | G20: 防水 | H20: 第 07121 章 橡化瀝青防水膜 | I20: B-002089-NEW-AR-000-DL-001 建築標準圖(1)牆面/地坪 | K20: 115/08/31 | M20: 115/08/31
C23: 7 | F23: 水和凝固型防水材(彈泥)/複合式防水材 | G23: 防水 | H23: 第 07145 章 水泥基防水 | I23: B-002089-NEW-AR-911-DG-039 防水隔熱詳圖二 | K23: 115/08/31 | M23: 115/08/31
C26: 8 | F26: PS隔熱板 | G26: 隔熱/防火 | H26: 第 07220 章 屋頂及樓板隔熱 | I26: B-002089-NEW-AR-000-DL-001 建築標準圖(1)牆面/地坪 | K26: 115/08/31 | M26: 115/08/31
C29: 9 | F29: 三明治板 | G29: 牆體/板材 | H29: 第07410章 金屬三明治夾心牆板 | I29: B-002089-NEW-AR-000-DL-010 建築標準圖(10)-複層金屬板外牆 | K29: 115/07/30 | M29: 115/07/30
C32: 10 | F32: 3mm熱熔式改質瀝青防水毯 | G32: 防水 | H32: 第 07505 章 屋頂防水層 | I32: B-002089-NEW-AR-911-DG-038 防水隔熱詳圖一 | K32: 115/08/31 | M32: 115/08/31
C35: 11 | F35: PU防水材 | G35: 防水 | H35: 第 07505 章 屋頂防水層 | I35: 設計圖說:B-002089-NEW-AR-911-DG-039 防水隔熱詳圖-二 | K35: 115/08/31 | M35: 115/08/31
C38: 12 | F38: 不鏽鋼框玻璃門 | G38: 門窗/玻璃 | H38: 第 08110-A章 鋼門扇及門樘 | I38: B-002089-NEW-AR-911-DG-008 門窗表(一) | K38: 115/08/31 | M38: 115/08/31
C41: 13 | D41: S-SB-50-034 | F41: 鋁製門窗材料送審與供料商 | G41: 門窗/玻璃 | H41: 第08120章-鋁門扇及門樘/第08520章-鋁窗 | I41: B-002089-NEW-AR-911-DG-008門窗表(一)~(五) | J41: 仟藝鋁業 | K41: 115/08/31 | L41: =IF(M41="","",M41-30) -> #VALUE! | M41: 115/08/31 | N41: =IF(K41="","",IF(R41<>"","",IF(AND(R41="",K41-TODAY()<=60),K41-TODAY(),""))) | O41: =IF(AND(ISNUMBER(K41),ISNUMBER(R41)),K41-R41,"") | P41: 核定 | Q41: 0-A | R41: 46048 | S41: 鼎水資字第1150000127號 | T41: 46058 | U41: 艾奕康水字第1150003545號 | V41: 審查同意 | W41: 46058 | X41: 艾奕康水字第1150003545號 | Y41: 審定 | Z41: 46112 | AA41: 水北多字第11522015640號 | AB41: 核定
N42: =IF(K42="","",IF(R42<>"","",IF(AND(R42="",K42-TODAY()<=60),K42-TODAY(),""))) | O42: =IF(AND(ISNUMBER(K42),ISNUMBER(R42)),K42-R42,"")
N43: =IF(K43="","",IF(R43<>"","",IF(AND(R43="",K43-TODAY()<=60),K43-TODAY(),""))) | O43: =IF(AND(ISNUMBER(K43),ISNUMBER(R43)),K43-R43,"")
C44: 14 | F44: 鍍鋅鋼板烤漆門(防火門、防火隔音門) | G44: 門窗/玻璃 | H44: 第 08170 章 防火金屬門扇及門樘 | I44: B-002089-NEW-AR-000-DG-003 廠區建築門窗表一 | K44: 115/08/31 | M44: 115/08/31
C47: 15 | F47: 電動鐵捲門(鍍鋁鋅鋼板、 不銹鋼、 鍍鋅鋼板) | G47: 門窗/玻璃 | H47: 第 08331 章 V6.0 鋼捲門 | I47: B-002089-NEW-AR-000-DG-005 廠區建築門窗-鋼捲門 | K47: 115/08/31 | M47: 115/08/31
C50: 16 | F50: 塑鋼窗/百葉 | G50: 門窗/玻璃 | H50: 第 08569-A 章 塑鋼窗 | I50: B-002089-NEW-AR-000-DG-004 廠區建築門窗表二 | K50: 115/08/31 | M50: 115/08/31
C53: 17 | D53: S-SB63-047 | F53: 玻璃(5mm清強化玻璃/8+8AS+8熱硬化LOW-E複層玻璃/5mm+5mm膠合強化玻璃) | G53: 門窗/玻璃 | H53: 第08810-A章玻璃 | I53: B-002089-NEW-AR-911-DG-008門窗表(一)~(五) | J53: 巨昇玻璃 | K53: 115/08/31 | M53: 115/08/31 | P53: 核定 | Q53: 0-A | R53: 46086 | S53: 鼎水資字第1150000395號 | T53: 115/3/30 | U53: 艾奕康水字第1150006255號 | V53: 審查同意 | W53: 115/3/30 | X53: 艾奕康水字第1150006255號 | Y53: 審查同意 | Z53: 115/4/21 | AA53: 水北多字第11522019380號 | AB53: 核定
C56: 18 | F56: 磁磚(石英磚/花崗石/塑膠地磚/磨石子) | G56: 地坪/鋪面 | H56: 第 09341 - A 章 鋪地磚 | I56: B-002089-NEW-AR-000-DG-026地坪大樣詳圖 | K56: 115/08/31 | M56: 115/08/31
C59: 19 | F59: 3mm/5mm環氧樹脂地坪 | G59: 地坪/鋪面 | H59: 第 09622-A 章 環氧樹脂砂漿地坪 | I59: B-002089-NEW-AR-000-DL-002 建築標準圖(2)-防水處理 B-002089-NEW-AR-911-DG-026 地坪大樣詳圖 | K59: 115/08/31 | M59: 115/08/31
C62: 20 | F62: 鋁合金高架地板 | G62: 地坪/鋪面 | I62: B-002089-NEW-AR-911-DG-026地坪大樣詳圖 | K62: 115/08/31 | M62: 115/08/31
C65: 21 | F65: 水性水泥漆 | G65: 塗裝 | H65: 第09912章水泥漆 | I65: B-002089-NEW-AR-911-DG-000 材料裝修表一 | K65: 115/08/31 | M65: 115/08/31
C68: 22 | F68: 環氧樹脂防蝕塗裝 | G68: 塗裝 | H68: 第 09961章環氧樹脂漆、第 09971章 防蝕塗裝 | I68: B-002089-NEW-AR-000-DL-002 建築標準圖(2)-防水處理 B-002089-NEW-AR-000-DG-001 廠區建築粉刷表(1/2) | K68: 115/08/31 | M68: 115/08/31
C71: 23 | F71: 仿清水膜塗裝 | G71: 塗裝 | I71: B-002089-NEW-AR-000-DL-004 建築標準圖(4)-仿清水膜塗裝 | K71: 115/08/31 | M71: 115/08/31
C74: 24 | F74: 氟碳烤漆 | G74: 門窗/玻璃 | H74: 第 09962-A 章 氟化聚合物塗料 | I74: B-002089-NEW-AR-911-DG-008門窗表(一)~(五) | K74: 115/08/31 | M74: 115/08/31
C77: 25 | F77: 防火玻璃窗(25mm防火玻璃)/防火百葉 | G77: 門窗/玻璃 | I77: B-002089-NEW-AR-000-DL-012 建築標準圖(12)-隔間牆/防火玻璃窗 | K77: 115/08/31 | M77: 115/08/31
C80: 26 | F80: 帷幕 | G80: 門窗/玻璃 | I80: B-002089-NEW-AR-911-DG-015 帷幕詳圖(一) | K80: 115/08/31 | M80: 115/08/31
C83: 27 | F83: 隔音門 | G83: 門窗/玻璃 | I83: B-002089-NEW-AR-000-DL-011 建築標準圖(11)-天花板/隔音門 | K83: 115/08/31 | M83: 115/08/31
C86: 28 | F86: 矽酸鈣板 | G86: 牆體/板材 | I86: B-002089-NEW-AR-911-DG-031 輕隔間大樣詳圖二 | K86: 115/07/30 | M86: 115/07/30
C89: 29 | F89: 防火石膏板 | G89: 牆體/板材 | I89: B-002089-NEW-AR-000-DL-012 建築標準圖(12)-隔間牆,防火玻璃窗 | K89: 115/07/30 | M89: 115/07/30
C92: 30 | F92: 防潮石膏板 | G92: 牆體/板材 | I92: B-002089-NEW-AR-911-DG-031 輕隔間大樣詳圖二 | K92: 115/07/30 | M92: 115/07/30
C95: 31 | F95: 纖維水泥板 | G95: 牆體/板材 | I95: B-002089-NEW-AR-911-DG-031 輕隔間大樣詳圖二 | K95: 115/07/30 | M95: 115/07/30
C98: 32 | F98: 瀝青底油 | G98: 防水 | I98: B-002089-NEW-AR-911-DG-038 防水隔熱詳圖一 | K98: 115/08/31 | M98: 115/08/31
...

Sheet 10-5消防空調給排水
B1: 新竹海水淡化廠興建及操作維護(興建部分) 消防空調給排水材料設備送審管制總表
A2: 品管現用版本項次 | B2: 項次 | C2: 編碼 | D2: English | E2: 文件 | F2: 優先順序 | G2: English | H2: 類別 | I2: 規範 | J2: 圖面 | K2: 廠商 | L2: 預定送審 (進場前60天) | M2: 預定廠驗 (進場前30天) | N2: 預定進場 | O2: 送審預警天數 (60天內才顯示) | P2: 送審延遲 | Q2: 程序 | R2: 版次 | S2: 審查情形 | AD2: 備註
O3: 辦理預警 | S3: 統包商 | U3: 監造 | X3: 專管 | AA3: 機關(北水分署)
S4: 日期 | T4: 文號 | U4: 日期 | V4: 文號 | W4: 結果 | X4: 日期 | Y4: 文號 | Z4: 結果 | AA4: 日期 | AB4: 文號 | AC4: 結果
A5: 87 | B5: 1 | E5: 火警警報設備 | G5: ELEC | H5: 機電 | I5: 第13851章 火警警報設備規範 | K5: 鼎岳 | L5: 46204 | M5: 46234 | N5: 46264 | O5: =IF(L5="","",IF(S5<>"","",IF(AND(S5="",L5-TODAY()<=60),L5-TODAY(),""))) -> 35 | P5: =IF(AND(ISNUMBER(L5),ISNUMBER(S5)),L5-S5,"") | R5: 0-A
O6: =IF(L6="","",IF(S6<>"","",IF(AND(S6="",L6-TODAY()<=60),L6-TODAY(),""))) | P6: =IF(AND(ISNUMBER(L6),ISNUMBER(S6)),L6-S6,"") | Z6: =IF(X6="","",IF(W6="檢退","檢退",IF(W6="審查同意","審定","檢退")))
O7: =IF(L7="","",IF(S7<>"","",IF(AND(S7="",L7-TODAY()<=60),L7-TODAY(),""))) | P7: =IF(AND(ISNUMBER(L7),ISNUMBER(S7)),L7-S7,"") | Z7: =IF(X7="","",IF(W7="檢退","檢退",IF(W7="審查同意","審定","檢退")))
A8: 88 | B8: 2 | E8: 消防火警受信總機 | L8: 46204 | M8: 46234 | N8: 46264 | O8: =IF(L8="","",IF(S8<>"","",IF(AND(S8="",L8-TODAY()<=60),L8-TODAY(),""))) -> 35 | P8: =IF(AND(ISNUMBER(L8),ISNUMBER(S8)),L8-S8,"") | R8: 0-A
A11: 89 | B11: 3 | E11: 消防廣播設備 | L11: 46204 | M11: 46234 | N11: 46264 | O11: =IF(L11="","",IF(S11<>"","",IF(AND(S11="",L11-TODAY()<=60),L11-TODAY(),""))) -> 35 | P11: =IF(AND(ISNUMBER(L11),ISNUMBER(S11)),L11-S11,"") | R11: 0-A
A14: 111 | B14: 4 | E14: 緊急廣播系統 | L14: 46204 | M14: 46234 | N14: 46264 | O14: =IF(L14="","",IF(S14<>"","",IF(AND(S14="",L14-TODAY()<=60),L14-TODAY(),""))) -> 35 | P14: =IF(AND(ISNUMBER(L14),ISNUMBER(S14)),L14-S14,"") | R14: 0-A
A17: 112 | B17: 5 | E17: 火警探測設備 | G17: ELEC | H17: 機電 | I17: 13853 章 火警探測設備 | K17: 鼎岳 | L17: 46204 | M17: 46234 | N17: 46264 | O17: =IF(L17="","",IF(S17<>"","",IF(AND(S17="",L17-TODAY()<=60),L17-TODAY(),""))) -> 35 | P17: =IF(AND(ISNUMBER(L17),ISNUMBER(S17)),L17-S17,"") | R17: 0-A | Z17: =IF(X17="","",IF(W17="檢退","檢退",IF(W17="審查同意","審定","檢退")))
O18: =IF(L18="","",IF(S18<>"","",IF(AND(S18="",L18-TODAY()<=60),L18-TODAY(),""))) | P18: =IF(AND(ISNUMBER(L18),ISNUMBER(S18)),L18-S18,"") | R18: 0-B | Z18: =IF(X18="","",IF(W18="檢退","檢退",IF(W18="審查同意","審定","檢退")))
O19: =IF(L19="","",IF(S19<>"","",IF(AND(S19="",L19-TODAY()<=60),L19-TODAY(),""))) | P19: =IF(AND(ISNUMBER(L19),ISNUMBER(S19)),L19-S19,"") | R19: 0-C | Z19: =IF(X19="","",IF(W19="檢退","檢退",IF(W19="審查同意","審定","檢退")))
B20: =B17+1 -> 6 | C20: S-SC15-015 | E20: 消防管材 | G20: MECH | H20: 機械 | I20: 13911 消防管材及施工方法 | K20: 鼎岳 | L20: 46204 | M20: 46234 | N20: 46264 | O20: =IF(L20="","",IF(S20<>"","",IF(AND(S20="",L20-TODAY()<=60),L20-TODAY(),""))) -> 35 | P20: =IF(AND(ISNUMBER(L20),ISNUMBER(S20)),L20-S20,"") | R20: 0-A | Z20: =IF(X20="","",IF(W20="檢退","檢退",IF(W20="審查同意","審定","檢退")))
O21: =IF(L21="","",IF(S21<>"","",IF(AND(S21="",L21-TODAY()<=60),L21-TODAY(),""))) | P21: =IF(AND(ISNUMBER(L21),ISNUMBER(S21)),L21-S21,"") | R21: 0-B | Z21: =IF(X21="","",IF(W21="檢退","檢退",IF(W21="審查同意","審定","檢退")))
O22: =IF(L22="","",IF(S22<>"","",IF(AND(S22="",L22-TODAY()<=60),L22-TODAY(),""))) | P22: =IF(AND(ISNUMBER(L22),ISNUMBER(S22)),L22-S22,"") | R22: 0-C | Z22: =IF(X22="","",IF(W22="檢退","檢退",IF(W22="審查同意","審定","檢退")))
B23: =B20+1 -> 7 | C23: S-SC02-0002 | E23: 消防泵浦設備及廠商資格-至盛工業 | G23: MECH | H23: 機械 | I23: 139120 消防泵 | K23: 鼎岳 | L23: 46204 | M23: 46234 | N23: 46264 | O23: =IF(L23="","",IF(S23<>"","",IF(AND(S23="",L23-TODAY()<=60),L23-TODAY(),""))) | P23: =IF(AND(ISNUMBER(L23),ISNUMBER(S23)),L23-S23,"") -> 223 | Q23: 修正 | R23: 0-A | S23: 45981 | T23: 鼎水資字第1140001378號 | U23: 45999 | V23: 艾奕康水字第1140033395號 | W23: 檢退-規範未核定
R24: 0-B
R25: 0-C
B26: =B23+1 -> 8 | E26: 污水管路 | G26: MECH | H26: 機械 | I26: 15151 汙水管路系統 | L26: 46204 | M26: 46234 | N26: 46264 | O26: =IF(L26="","",IF(S26<>"","",IF(AND(S26="",L26-TODAY()<=60),L26-TODAY(),""))) -> 35 | P26: =IF(AND(ISNUMBER(L26),ISNUMBER(S26)),L26-S26,"") | R26: 0-A
O27: =IF(L27="","",IF(S27<>"","",IF(AND(S27="",L27-TODAY()<=60),L27-TODAY(),""))) | P27: =IF(AND(ISNUMBER(L27),ISNUMBER(S27)),L27-S27,"") | R27: 0-B | Z27: =IF(X27="","",IF(W27="檢退","檢退",IF(W27="審查同意","審定","檢退")))
O28: =IF(L28="","",IF(S28<>"","",IF(AND(S28="",L28-TODAY()<=60),L28-TODAY(),""))) | P28: =IF(AND(ISNUMBER(L28),ISNUMBER(S28)),L28-S28,"") | R28: 0-C | Z28: =IF(X28="","",IF(W28="檢退","檢退",IF(W28="審查同意","審定","檢退")))
B29: =B26+1 -> 9 | E29: 自來水不銹鋼管及管件 | G29: MECH | H29: 機械 | I29: 15223 自來水不銹鋼管及管件 | L29: 46204 | M29: 46234 | N29: 46264 | O29: =IF(L29="","",IF(S29<>"","",IF(AND(S29="",L29-TODAY()<=60),L29-TODAY(),""))) -> 35 | P29: =IF(AND(ISNUMBER(L29),ISNUMBER(S29)),L29-S29,"") | R29: 0-A
O30: =IF(L30="","",IF(S30<>"","",IF(AND(S30="",L30-TODAY()<=60),L30-TODAY(),""))) | P30: =IF(AND(ISNUMBER(L30),ISNUMBER(S30)),L30-S30,"") | R30: 0-B | Z30: =IF(X30="","",IF(W30="檢退","檢退",IF(W30="審查同意","審定","檢退")))
O31: =IF(L31="","",IF(S31<>"","",IF(AND(S31="",L31-TODAY()<=60),L31-TODAY(),""))) | P31: =IF(AND(ISNUMBER(L31),ISNUMBER(S31)),L31-S31,"") | R31: 0-C | Z31: =IF(X31="","",IF(W31="檢退","檢退",IF(W31="審查同意","審定","檢退")))
B32: =B29+1 -> 10 | E32: 自來水不銹鋼伸縮接頭 | G32: MECH | H32: 機械 | I32: 15224 自來水不銹鋼伸縮接頭 | L32: 46204 | M32: 46234 | N32: 46264 | O32: =IF(L32="","",IF(S32<>"","",IF(AND(S32="",L32-TODAY()<=60),L32-TODAY(),""))) -> 35 | P32: =IF(AND(ISNUMBER(L32),ISNUMBER(S32)),L32-S32,"") | R32: 0-A
O33: =IF(L33="","",IF(S33<>"","",IF(AND(S33="",L33-TODAY()<=60),L33-TODAY(),""))) | P33: =IF(AND(ISNUMBER(L33),ISNUMBER(S33)),L33-S33,"") | R33: 0-B | Z33: =IF(X33="","",IF(W33="檢退","檢退",IF(W33="審查同意","審定","檢退")))
O34: =IF(L34="","",IF(S34<>"","",IF(AND(S34="",L34-TODAY()<=60),L34-TODAY(),""))) | P34: =IF(AND(ISNUMBER(L34),ISNUMBER(S34)),L34-S34,"") | R34: 0-C | Z34: =IF(X34="","",IF(W34="檢退","檢退",IF(W34="審查同意","審定","檢退")))
A35: 100 | B35: =B32+1 -> 11 | E35: 給排水及衛生器具 | G35: MECH | H35: 機械 | I35: 第 15410 章 給排水及衛生器具 | L35: 46204 | M35: 46234 | N35: 46264 | O35: 16 | R35: 0-A
R36: 0-B | Z36: =IF(X36="","",IF(W36="檢退","檢退",IF(W36="審查同意","審定","檢退")))
R37: 0-C | Z37: =IF(X37="","",IF(W37="檢退","檢退",IF(W37="審查同意","審定","檢退")))
A38: 101 | B38: =B35+1 -> 12 | E38: 衛生給排水泵 | G38: MECH | H38: 機械 | I38: 第 15440 章 衛生給排水泵 | L38: 46204 | M38: 46234 | N38: 46264 | O38: 16 | R38: 0-A
R39: 0-B | Z39: =IF(X39="","",IF(W39="檢退","檢退",IF(W39="審查同意","審定","檢退")))
R40: 0-C | Z40: =IF(X40="","",IF(W40="檢退","檢退",IF(W40="審查同意","審定","檢退")))
B41: =B38+1 -> 13 | E41: 分離式空調機組 | G41: MECH | H41: 機械 | I41: 第 15737 章 分離式空調機組 | L41: 46204 | M41: 46234 | N41: 46264 | O41: 16 | R41: 0-A
R42: 0-B | Z42: =IF(X42="","",IF(W42="檢退","檢退",IF(W42="審查同意","審定","檢退")))
R43: 0-C | Z43: =IF(X43="","",IF(W43="檢退","檢退",IF(W43="審查同意","審定","檢退")))
B44: =B41+1 -> 14 | E44: 空調風管附屬設備元入件 | G44: MECH | H44: 機械 | I44: 第 15820 章 空調風管附屬設備元件 | L44: 46204 | M44: 46234 | N44: 46264 | O44: 16 | R44: 0-A
R45: 0-B | Z45: =IF(X45="","",IF(W45="檢退","檢退",IF(W45="審查同意","審定","檢退")))
R46: 0-C | Z46: =IF(X46="","",IF(W46="檢退","檢退",IF(W46="審查同意","審定","檢退")))
...

Sheet 10-6機械設備
C1: 新竹海水淡化廠興建及操作維護(興建部分) 機械設備材料設備送審管制總表
A2: 窗口負責人 | B2: 品管現用版本項次 | C2: 項次 | D2: PN | E2: 文件編碼 | F2: 設備名稱 | G2: 設備名稱 (PCC 文件) | H2: 規範 | I2: 預定送審 (進場前60天) | J2: 預定廠驗 (進場前30天) | K2: 預定進場 | L2: 送審預警天數(60天內) | M2: 送審延遲 | N2: 程序 | O2: 版次 | P2: 審查情形 (廠商資格 stage2) | AA2: 備註 | AB2: 編碼 | AC2: 版次 | AD2: 審查情形 (設備型錄圖說 stage3, if applicable) | AO2: 備註
L3: 辦理預警 | P3: 統包商 | R3: 監造 | U3: 專管 | X3: 機關(北水分署) | AD3: 統包商 | AF3: 監造 | AI3: 專管 | AL3: 機關(北水分署)
P4: 日期 | Q4: 文號 | R4: 日期 | S4: 文號 | T4: 結果 | U4: 日期 | V4: 文號 | W4: 結果 | X4: 日期 | Y4: 文號 | Z4: 結果 | AD4: 日期 | AE4: 文號 | AF4: 日期 | AG4: 文號 | AH4: 結果 | AI4: 日期 | AJ4: 文號 | AK4: 結果 | AL4: 日期 | AM4: 文號 | AN4: 結果
B5: 82 | C5: 1 | D5: 126+141 | E5: S-SC501-501 (CTC-DC-000-SD-501) | F5: GRP PIPES (AG & UG) + PUDDLE PIPES | G5: GRP管線(Future Pipe Industries) | H5: 第02533A章 玻璃纖維增強塑膠管材 | I5: =IF(K5="","",K5-60) -> 45950 | J5: =IF(K5="","",K5-30) -> 45980 | K5: 46010 | L5: =IF(I5="","",IF(P5<>"","",IF(AND(P5="",I5-TODAY()<=60),I5-TODAY(),""))) | M5: =IF(COUNT(I5, P5)=2, I5-P5, "") -> 41 | O5: 0-A | P5: 45909 | Q5: 鼎水資字第1140000932號 | R5: 45919 | S5: 艾奕康水字第1140026972號 | T5: 檢退-規範未核定 | AB5: S-SC22-022 | AC5: 0-A | AD5: 46064 | AE5: 鼎水資字第1150000271號 | AF5: 46090 | AG5: 艾奕康水字第1150004570號 | AH5: 審查同意 | AI5: 46090 | AJ5: 艾奕康水字第1150004570號 | AK5: 審定
L6: =IF(I6="","",IF(P6<>"","",IF(AND(P6="",I6-TODAY()<=60),I6-TODAY(),""))) | M6: =IF(COUNT(I6, P6)=2, I6-P6, "") | O6: 0-B | P6: 46062 | Q6: 鼎水資字第1150000234號 | R6: 46097 | S6: 艾奕康水字第1150004921號 | T6: 審查同意 | U6: 46097 | V6: 艾奕康水字第1150004921號 | W6: 審定 | X6: 46121 | Y6: 水北多字第11522016890號 | Z6: 核定 | AC6: 0-B | AD6: 46134 | AE6: 鼎水資字第1150000666號
L7: =IF(I7="","",IF(P7<>"","",IF(AND(P7="",I7-TODAY()<=60),I7-TODAY(),""))) | M7: =IF(COUNT(I7, P7)=2, I7-P7, "") | N7: 審查 | O7: 1-A | P7: 46149 | Q7: 鼎水資字第1150000730號
B8: 67 | C8: 2 | D8: 9 | E8: S-SC541-541 (CTC-DC-000-SD-004) | F8: Agitator equipment COAGULATION CHAMBER MIXERS | G8: 攪拌器 COAGULATION MIXER | H8: 第11221章 攪拌器 | I8: =IF(J8="","",J8-30) -> 46143 | J8: =IF(K8="","",K8-30) -> 46173 | K8: 46203 | L8: =IF(I8="","",IF(P8<>"","",IF(AND(P8="",I8-TODAY()<=60),I8-TODAY(),""))) | M8: =IF(COUNT(I8, P8)=2, I8-P8, "") -> 157 | O8: 0-A | P8: 45986 | Q8: 鼎水資字第1140001401號 | R8: 46007 | S8: 艾奕康水字第1140033597號 | T8: 檢退 | AB8: S-SC39-039 | AC8: 0-A | AD8: 46119 | AE8: 鼎水資字第1150000549號 | AF8: 46134 | AG8: 艾奕康水字第1150008634號 | AH8: 審查同意 | AI8: 46134 | AJ8: 艾奕康水字第1150008634號 | AK8: 審定 | AL8: 46148 | AM8: 水北多字第11522022840號 | AN8: 核定
B9: 113 | L9: =IF(I9="","",IF(P9<>"","",IF(AND(P9="",I9-TODAY()<=60),I9-TODAY(),""))) | M9: =IF(COUNT(I9, P9)=2, I9-P9, "") | N9: 核定 | O9: 0-B | P9: 46066 | Q9: 鼎水資字第1150000301號 | R9: 46105 | S9: 艾奕康水字第1150005667號 | T9: 審查同意 | U9: 46105 | V9: 艾奕康水字第1150005667號 | W9: 審定 | X9: 46133 | Y9: 水北多字第11522019360號 | Z9: 核定
L10: =IF(I10="","",IF(P10<>"","",IF(AND(P10="",I10-TODAY()<=60),I10-TODAY(),""))) | M10: =IF(COUNT(I10, P10)=2, I10-P10, "") | O10: 0-C
B11: 115 | C11: 3 | D11: 63 | E11: S-SC541-541 (CTC-DC-000-SD-004) | F11: THICKENED SLUDGE TANK SUBMERSIBLE MIXER | G11: 濃縮污泥池攪拌器 THICKENED SLUDGE TANK MIXER | H11: 第11221章 攪拌器 | I11: =IF(J11="","",J11-30) -> 46016 | J11: =IF(K11="","",K11-30) -> 46046 | K11: 46076 | L11: =IF(I11="","",IF(P11<>"","",IF(AND(P11="",I11-TODAY()<=60),I11-TODAY(),""))) | M11: =IF(COUNT(I11, P11)=2, I11-P11, "") -> 30 | O11: 0-A | P11: 45986 | Q11: 鼎水資字第1140001401號 | R11: 46007 | S11: 艾奕康水字第1140033597號 | T11: 檢退 | AB11: S-SC39-039 | AC11: 0-A | AD11: 46119 | AE11: 鼎水資字第1150000549號 | AF11: 46134 | AG11: 艾奕康水字第1150008634號 | AH11: 審查同意 | AI11: 46134 | AJ11: 艾奕康水字第1150008634號 | AK11: 審定
L12: =IF(I12="","",IF(P12<>"","",IF(AND(P12="",I12-TODAY()<=60),I12-TODAY(),""))) | M12: =IF(COUNT(I12, P12)=2, I12-P12, "") | N12: 核定 | O12: 0-B | P12: 46066 | Q12: 鼎水資字第1150000301號 | R12: 46105 | S12: 艾奕康水字第1150005667號 | T12: 審查同意 | U12: 46105 | V12: 艾奕康水字第1150005667號 | W12: 審定 | X12: 46133 | Y12: 水北多字第11522019360號 | Z12: 核定
L13: =IF(I13="","",IF(P13<>"","",IF(AND(P13="",I13-TODAY()<=60),I13-TODAY(),""))) | M13: =IF(COUNT(I13, P13)=2, I13-P13, "") | O13: 0-C
B14: 69 | C14: 4 | D14: 89 | F14: HOISTS | G14: GRP玻璃纖維儲槽 | H14: 第11241章 玻璃纖維儲槽 | I14: =IF(K14="","",K14-60) -> 46173 | J14: =IF(K14="","",K14-30) -> 46203 | K14: 46233 | L14: =IF(I14="","",IF(P14<>"","",IF(AND(P14="",I14-TODAY()<=60),I14-TODAY(),""))) -> 4 | M14: =IF(COUNT(I14, P14)=2, I14-P14, "") | O14: 0-A
L15: =IF(I15="","",IF(P15<>"","",IF(AND(P15="",I15-TODAY()<=60),I15-TODAY(),""))) | M15: =IF(COUNT(I15, P15)=2, I15-P15, "") | O15: 0-B
L16: =IF(I16="","",IF(P16<>"","",IF(AND(P16="",I16-TODAY()<=60),I16-TODAY(),""))) | M16: =IF(COUNT(I16, P16)=2, I16-P16, "") | O16: 0-C
